2021-04-22 16:15:15,667 - INFO - Started server process [13134]
2021-04-22 16:15:15,668 - INFO - Waiting for application startup.
2021-04-22 16:15:15,669 - INFO - Application startup complete.
2021-04-22 16:15:15,670 - INFO - Uvicorn running on http://0.0.0.0:8081 (Press CTRL+C to quit)
2021-04-22 16:16:32,260 - INFO - Shutting down
2021-04-22 16:16:32,361 - INFO - Waiting for application shutdown.
2021-04-22 16:16:32,362 - INFO - Application shutdown complete.
2021-04-22 16:16:32,362 - INFO - Finished server process [13134]
2021-04-22 16:18:16,478 - INFO - Started server process [13186]
2021-04-22 16:18:16,479 - INFO - Waiting for application startup.
2021-04-22 16:18:16,479 - INFO - Application startup complete.
2021-04-22 16:18:16,479 - INFO - Uvicorn running on http://0.0.0.0:8081 (Press CTRL+C to quit)
2021-04-22 16:22:57,546 - INFO - Shutting down
2021-04-22 16:22:57,647 - INFO - Waiting for application shutdown.
2021-04-22 16:22:57,647 - INFO - Application shutdown complete.
2021-04-22 16:22:57,647 - INFO - Finished server process [13186]
2021-04-22 16:22:59,808 - INFO - Started server process [13192]
2021-04-22 16:22:59,808 - INFO - Waiting for application startup.
2021-04-22 16:22:59,809 - INFO - Application startup complete.
2021-04-22 16:22:59,809 - INFO - Uvicorn running on http://0.0.0.0:8081 (Press CTRL+C to quit)
2021-04-22 16:23:35,248 - INFO - Shutting down
2021-04-22 16:23:35,348 - INFO - Waiting for application shutdown.
2021-04-22 16:23:35,349 - INFO - Application shutdown complete.
2021-04-22 16:23:35,349 - INFO - Finished server process [13192]
2021-04-22 16:23:43,858 - INFO - Started server process [13197]
2021-04-22 16:23:43,859 - INFO - Waiting for application startup.
2021-04-22 16:23:43,860 - INFO - Application startup complete.
2021-04-22 16:23:43,860 - INFO - Uvicorn running on http://0.0.0.0:8081 (Press CTRL+C to quit)
2021-04-22 16:28:27,719 - INFO - Shutting down
2021-04-22 16:28:27,820 - INFO - Waiting for application shutdown.
2021-04-22 16:28:27,821 - INFO - Application shutdown complete.
2021-04-22 16:28:27,821 - INFO - Finished server process [13197]
2021-04-22 17:19:52,478 - INFO - Started server process [13287]
2021-04-22 17:19:52,478 - INFO - Waiting for application startup.
2021-04-22 17:19:52,479 - INFO - Application startup complete.
2021-04-22 17:19:52,479 - INFO - Uvicorn running on http://0.0.0.0:8081 (Press CTRL+C to quit)
2021-04-22 17:20:53,399 - INFO - Shutting down
2021-04-22 17:20:53,500 - INFO - Waiting for application shutdown.
2021-04-22 17:20:53,500 - INFO - Application shutdown complete.
2021-04-22 17:20:53,500 - INFO - Finished server process [13287]
2021-04-22 17:21:38,342 - INFO - Started server process [13296]
2021-04-22 17:21:38,342 - INFO - Waiting for application startup.
2021-04-22 17:21:38,343 - INFO - Application startup complete.
2021-04-22 17:21:38,343 - INFO - Uvicorn running on http://0.0.0.0:8081 (Press CTRL+C to quit)
2021-04-22 17:55:42,840 - INFO - Shutting down
2021-04-22 17:55:42,940 - INFO - Waiting for application shutdown.
2021-04-22 17:55:42,941 - INFO - Application shutdown complete.
2021-04-22 17:55:42,941 - INFO - Finished server process [13296]
2021-04-22 17:58:37,663 - INFO - Started server process [13361]
2021-04-22 17:58:37,663 - INFO - Waiting for application startup.
2021-04-22 17:58:37,664 - INFO - Application startup complete.
2021-04-22 17:58:37,664 - INFO - Uvicorn running on http://0.0.0.0:8081 (Press CTRL+C to quit)
2021-04-22 17:58:50,209 - INFO - Shutting down
2021-04-22 17:58:50,310 - INFO - Waiting for application shutdown.
2021-04-22 17:58:50,311 - INFO - Application shutdown complete.
2021-04-22 17:58:50,311 - INFO - Finished server process [13361]
2021-04-22 18:03:14,044 - INFO - Started server process [13398]
2021-04-22 18:03:14,044 - INFO - Waiting for application startup.
2021-04-22 18:03:14,045 - INFO - Application startup complete.
2021-04-22 18:03:14,046 - INFO - Uvicorn running on http://0.0.0.0:8081 (Press CTRL+C to quit)
2021-04-22 18:10:43,990 - ERROR - Exception in ASGI application
Traceback (most recent call last):
  File "/home/pot/.conda/envs/tf_2.4.1_cpu/lib/python3.8/site-packages/uvicorn/protocols/http/h11_impl.py", line 396, in run_asgi
    result = await app(self.scope, self.receive, self.send)
  File "/home/pot/.conda/envs/tf_2.4.1_cpu/lib/python3.8/site-packages/uvicorn/middleware/proxy_headers.py", line 45, in __call__
    return await self.app(scope, receive, send)
  File "/home/pot/.conda/envs/tf_2.4.1_cpu/lib/python3.8/site-packages/uvicorn/middleware/debug.py", line 81, in __call__
    raise exc from None
  File "/home/pot/.conda/envs/tf_2.4.1_cpu/lib/python3.8/site-packages/uvicorn/middleware/debug.py", line 78, in __call__
    await self.app(scope, receive, inner_send)
  File "/home/pot/.conda/envs/tf_2.4.1_cpu/lib/python3.8/site-packages/fastapi/applications.py", line 199, in __call__
    await super().__call__(scope, receive, send)
  File "/home/pot/.conda/envs/tf_2.4.1_cpu/lib/python3.8/site-packages/starlette/applications.py", line 111, in __call__
    await self.middleware_stack(scope, receive, send)
  File "/home/pot/.conda/envs/tf_2.4.1_cpu/lib/python3.8/site-packages/starlette/middleware/errors.py", line 181, in __call__
    raise exc from None
  File "/home/pot/.conda/envs/tf_2.4.1_cpu/lib/python3.8/site-packages/starlette/middleware/errors.py", line 159, in __call__
    await self.app(scope, receive, _send)
  File "/home/pot/.conda/envs/tf_2.4.1_cpu/lib/python3.8/site-packages/starlette/middleware/base.py", line 25, in __call__
    response = await self.dispatch_func(request, self.call_next)
  File "main.py", line 43, in db_session_middleware
    response = await call_next(request)
  File "/home/pot/.conda/envs/tf_2.4.1_cpu/lib/python3.8/site-packages/starlette/middleware/base.py", line 45, in call_next
    task.result()
  File "/home/pot/.conda/envs/tf_2.4.1_cpu/lib/python3.8/site-packages/starlette/middleware/base.py", line 38, in coro
    await self.app(scope, receive, send)
  File "/home/pot/.conda/envs/tf_2.4.1_cpu/lib/python3.8/site-packages/starlette/middleware/cors.py", line 86, in __call__
    await self.simple_response(scope, receive, send, request_headers=headers)
  File "/home/pot/.conda/envs/tf_2.4.1_cpu/lib/python3.8/site-packages/starlette/middleware/cors.py", line 142, in simple_response
    await self.app(scope, receive, send)
  File "/home/pot/.conda/envs/tf_2.4.1_cpu/lib/python3.8/site-packages/starlette/exceptions.py", line 82, in __call__
    raise exc from None
  File "/home/pot/.conda/envs/tf_2.4.1_cpu/lib/python3.8/site-packages/starlette/exceptions.py", line 71, in __call__
    await self.app(scope, receive, sender)
  File "/home/pot/.conda/envs/tf_2.4.1_cpu/lib/python3.8/site-packages/starlette/routing.py", line 566, in __call__
    await route.handle(scope, receive, send)
  File "/home/pot/.conda/envs/tf_2.4.1_cpu/lib/python3.8/site-packages/starlette/routing.py", line 227, in handle
    await self.app(scope, receive, send)
  File "/home/pot/.conda/envs/tf_2.4.1_cpu/lib/python3.8/site-packages/starlette/routing.py", line 41, in app
    response = await func(request)
  File "/home/pot/.conda/envs/tf_2.4.1_cpu/lib/python3.8/site-packages/fastapi/routing.py", line 201, in app
    raw_response = await run_endpoint_function(
  File "/home/pot/.conda/envs/tf_2.4.1_cpu/lib/python3.8/site-packages/fastapi/routing.py", line 150, in run_endpoint_function
    return await run_in_threadpool(dependant.call, **values)
  File "/home/pot/.conda/envs/tf_2.4.1_cpu/lib/python3.8/site-packages/starlette/concurrency.py", line 34, in run_in_threadpool
    return await loop.run_in_executor(None, func, *args)
  File "/home/pot/.conda/envs/tf_2.4.1_cpu/lib/python3.8/concurrent/futures/thread.py", line 57, in run
    result = self.fn(*self.args, **self.kwargs)
  File "/home/pot/project/web-service/backend/app/api/resources/workflow_v1.py", line 19, in get_identity_card_by_day
    {'id': 1, 'status_code': 100, 'status_name': 'import', description: 'import', 'create_date': '2021-04-16'},
  File "/home/pot/project/web-service/backend/app/databases/repository_logic/document_logic.py", line 11, in get_list_document_by_date
    return db_session.query(Document) \
AttributeError: 'Query' object has no attribute 'option'
2021-04-22 18:13:10,337 - INFO - Shutting down
2021-04-22 18:13:10,438 - INFO - Waiting for application shutdown.
2021-04-22 18:13:10,439 - INFO - Application shutdown complete.
2021-04-22 18:13:10,439 - INFO - Finished server process [13398]
2021-04-22 18:13:22,577 - INFO - Started server process [13413]
2021-04-22 18:13:22,578 - INFO - Waiting for application startup.
2021-04-22 18:13:22,578 - INFO - Application startup complete.
2021-04-22 18:13:22,578 - INFO - Uvicorn running on http://0.0.0.0:8081 (Press CTRL+C to quit)
2021-04-22 18:13:27,425 - INFO - BEGIN (implicit)
2021-04-22 18:13:27,433 - INFO - SELECT document.id AS document_id, document.name AS document_name, document.url AS document_url, document.export_date AS document_export_date, document.create_date AS document_create_date, document.update_date AS document_update_date, document.type_id AS document_type_id, document.status_id AS document_status_id, document_type_1.id AS document_type_1_id, document_type_1.name AS document_type_1_name, document_type_1.description AS document_type_1_description, document_type_1.create_date AS document_type_1_create_date, document_type_1.update_date AS document_type_1_update_date, status_1.id AS status_1_id, status_1.status_code AS status_1_status_code, status_1.status_name AS status_1_status_name, status_1.description AS status_1_description, status_1.create_date AS status_1_create_date, status_1.update_date AS status_1_update_date, document_split_1.id AS document_split_1_id, document_split_1.name AS document_split_1_name, document_split_1.value AS document_split_1_value, document_split_1.is_extracted AS document_split_1_is_extracted, document_split_1.url AS document_split_1_url, document_split_1.create_date AS document_split_1_create_date, document_split_1.update_date AS document_split_1_update_date, document_split_1.type_id AS document_split_1_type_id, document_split_1.document_id AS document_split_1_document_id 
FROM document LEFT OUTER JOIN document_type AS document_type_1 ON document_type_1.id = document.type_id LEFT OUTER JOIN status AS status_1 ON status_1.id = document.status_id LEFT OUTER JOIN document_split AS document_split_1 ON document.id = document_split_1.document_id 
WHERE document.type_id = ? AND document.status_id = ? AND document.export_date = ? ORDER BY document.export_date DESC
2021-04-22 18:13:27,433 - INFO - [generated in 0.00042s] ('1', 3, '2021-04-22')
2021-04-22 18:13:27,436 - ERROR - Exception in ASGI application
Traceback (most recent call last):
  File "/home/pot/.conda/envs/tf_2.4.1_cpu/lib/python3.8/site-packages/uvicorn/protocols/http/h11_impl.py", line 396, in run_asgi
    result = await app(self.scope, self.receive, self.send)
  File "/home/pot/.conda/envs/tf_2.4.1_cpu/lib/python3.8/site-packages/uvicorn/middleware/proxy_headers.py", line 45, in __call__
    return await self.app(scope, receive, send)
  File "/home/pot/.conda/envs/tf_2.4.1_cpu/lib/python3.8/site-packages/uvicorn/middleware/debug.py", line 81, in __call__
    raise exc from None
  File "/home/pot/.conda/envs/tf_2.4.1_cpu/lib/python3.8/site-packages/uvicorn/middleware/debug.py", line 78, in __call__
    await self.app(scope, receive, inner_send)
  File "/home/pot/.conda/envs/tf_2.4.1_cpu/lib/python3.8/site-packages/fastapi/applications.py", line 199, in __call__
    await super().__call__(scope, receive, send)
  File "/home/pot/.conda/envs/tf_2.4.1_cpu/lib/python3.8/site-packages/starlette/applications.py", line 111, in __call__
    await self.middleware_stack(scope, receive, send)
  File "/home/pot/.conda/envs/tf_2.4.1_cpu/lib/python3.8/site-packages/starlette/middleware/errors.py", line 181, in __call__
    raise exc from None
  File "/home/pot/.conda/envs/tf_2.4.1_cpu/lib/python3.8/site-packages/starlette/middleware/errors.py", line 159, in __call__
    await self.app(scope, receive, _send)
  File "/home/pot/.conda/envs/tf_2.4.1_cpu/lib/python3.8/site-packages/starlette/middleware/base.py", line 25, in __call__
    response = await self.dispatch_func(request, self.call_next)
  File "main.py", line 43, in db_session_middleware
    response = await call_next(request)
  File "/home/pot/.conda/envs/tf_2.4.1_cpu/lib/python3.8/site-packages/starlette/middleware/base.py", line 45, in call_next
    task.result()
  File "/home/pot/.conda/envs/tf_2.4.1_cpu/lib/python3.8/site-packages/starlette/middleware/base.py", line 38, in coro
    await self.app(scope, receive, send)
  File "/home/pot/.conda/envs/tf_2.4.1_cpu/lib/python3.8/site-packages/starlette/middleware/cors.py", line 86, in __call__
    await self.simple_response(scope, receive, send, request_headers=headers)
  File "/home/pot/.conda/envs/tf_2.4.1_cpu/lib/python3.8/site-packages/starlette/middleware/cors.py", line 142, in simple_response
    await self.app(scope, receive, send)
  File "/home/pot/.conda/envs/tf_2.4.1_cpu/lib/python3.8/site-packages/starlette/exceptions.py", line 82, in __call__
    raise exc from None
  File "/home/pot/.conda/envs/tf_2.4.1_cpu/lib/python3.8/site-packages/starlette/exceptions.py", line 71, in __call__
    await self.app(scope, receive, sender)
  File "/home/pot/.conda/envs/tf_2.4.1_cpu/lib/python3.8/site-packages/starlette/routing.py", line 566, in __call__
    await route.handle(scope, receive, send)
  File "/home/pot/.conda/envs/tf_2.4.1_cpu/lib/python3.8/site-packages/starlette/routing.py", line 227, in handle
    await self.app(scope, receive, send)
  File "/home/pot/.conda/envs/tf_2.4.1_cpu/lib/python3.8/site-packages/starlette/routing.py", line 41, in app
    response = await func(request)
  File "/home/pot/.conda/envs/tf_2.4.1_cpu/lib/python3.8/site-packages/fastapi/routing.py", line 201, in app
    raw_response = await run_endpoint_function(
  File "/home/pot/.conda/envs/tf_2.4.1_cpu/lib/python3.8/site-packages/fastapi/routing.py", line 150, in run_endpoint_function
    return await run_in_threadpool(dependant.call, **values)
  File "/home/pot/.conda/envs/tf_2.4.1_cpu/lib/python3.8/site-packages/starlette/concurrency.py", line 34, in run_in_threadpool
    return await loop.run_in_executor(None, func, *args)
  File "/home/pot/.conda/envs/tf_2.4.1_cpu/lib/python3.8/concurrent/futures/thread.py", line 57, in run
    result = self.fn(*self.args, **self.kwargs)
  File "/home/pot/project/web-service/backend/app/api/resources/workflow_v1.py", line 31, in get_identity_card_by_day
    return data.name
AttributeError: 'list' object has no attribute 'name'
2021-04-22 18:13:57,714 - INFO - Shutting down
2021-04-22 18:13:57,815 - INFO - Waiting for application shutdown.
2021-04-22 18:13:57,815 - INFO - Application shutdown complete.
2021-04-22 18:13:57,815 - INFO - Finished server process [13413]
2021-04-22 18:13:59,195 - INFO - Started server process [13416]
2021-04-22 18:13:59,195 - INFO - Waiting for application startup.
2021-04-22 18:13:59,196 - INFO - Application startup complete.
2021-04-22 18:13:59,196 - INFO - Uvicorn running on http://0.0.0.0:8081 (Press CTRL+C to quit)
2021-04-22 18:14:00,784 - INFO - BEGIN (implicit)
2021-04-22 18:14:00,794 - INFO - SELECT document.id AS document_id, document.name AS document_name, document.url AS document_url, document.export_date AS document_export_date, document.create_date AS document_create_date, document.update_date AS document_update_date, document.type_id AS document_type_id, document.status_id AS document_status_id, document_type_1.id AS document_type_1_id, document_type_1.name AS document_type_1_name, document_type_1.description AS document_type_1_description, document_type_1.create_date AS document_type_1_create_date, document_type_1.update_date AS document_type_1_update_date, status_1.id AS status_1_id, status_1.status_code AS status_1_status_code, status_1.status_name AS status_1_status_name, status_1.description AS status_1_description, status_1.create_date AS status_1_create_date, status_1.update_date AS status_1_update_date, document_split_1.id AS document_split_1_id, document_split_1.name AS document_split_1_name, document_split_1.value AS document_split_1_value, document_split_1.is_extracted AS document_split_1_is_extracted, document_split_1.url AS document_split_1_url, document_split_1.create_date AS document_split_1_create_date, document_split_1.update_date AS document_split_1_update_date, document_split_1.type_id AS document_split_1_type_id, document_split_1.document_id AS document_split_1_document_id 
FROM document LEFT OUTER JOIN document_type AS document_type_1 ON document_type_1.id = document.type_id LEFT OUTER JOIN status AS status_1 ON status_1.id = document.status_id LEFT OUTER JOIN document_split AS document_split_1 ON document.id = document_split_1.document_id 
WHERE document.type_id = ? AND document.status_id = ? AND document.export_date = ? ORDER BY document.export_date DESC
2021-04-22 18:14:00,795 - INFO - [generated in 0.00095s] ('1', 3, '2021-04-22')
2021-04-22 18:14:00,798 - ERROR - Exception in ASGI application
Traceback (most recent call last):
  File "/home/pot/.conda/envs/tf_2.4.1_cpu/lib/python3.8/site-packages/uvicorn/protocols/http/h11_impl.py", line 396, in run_asgi
    result = await app(self.scope, self.receive, self.send)
  File "/home/pot/.conda/envs/tf_2.4.1_cpu/lib/python3.8/site-packages/uvicorn/middleware/proxy_headers.py", line 45, in __call__
    return await self.app(scope, receive, send)
  File "/home/pot/.conda/envs/tf_2.4.1_cpu/lib/python3.8/site-packages/uvicorn/middleware/debug.py", line 81, in __call__
    raise exc from None
  File "/home/pot/.conda/envs/tf_2.4.1_cpu/lib/python3.8/site-packages/uvicorn/middleware/debug.py", line 78, in __call__
    await self.app(scope, receive, inner_send)
  File "/home/pot/.conda/envs/tf_2.4.1_cpu/lib/python3.8/site-packages/fastapi/applications.py", line 199, in __call__
    await super().__call__(scope, receive, send)
  File "/home/pot/.conda/envs/tf_2.4.1_cpu/lib/python3.8/site-packages/starlette/applications.py", line 111, in __call__
    await self.middleware_stack(scope, receive, send)
  File "/home/pot/.conda/envs/tf_2.4.1_cpu/lib/python3.8/site-packages/starlette/middleware/errors.py", line 181, in __call__
    raise exc from None
  File "/home/pot/.conda/envs/tf_2.4.1_cpu/lib/python3.8/site-packages/starlette/middleware/errors.py", line 159, in __call__
    await self.app(scope, receive, _send)
  File "/home/pot/.conda/envs/tf_2.4.1_cpu/lib/python3.8/site-packages/starlette/middleware/base.py", line 25, in __call__
    response = await self.dispatch_func(request, self.call_next)
  File "main.py", line 43, in db_session_middleware
    response = await call_next(request)
  File "/home/pot/.conda/envs/tf_2.4.1_cpu/lib/python3.8/site-packages/starlette/middleware/base.py", line 45, in call_next
    task.result()
  File "/home/pot/.conda/envs/tf_2.4.1_cpu/lib/python3.8/site-packages/starlette/middleware/base.py", line 38, in coro
    await self.app(scope, receive, send)
  File "/home/pot/.conda/envs/tf_2.4.1_cpu/lib/python3.8/site-packages/starlette/middleware/cors.py", line 86, in __call__
    await self.simple_response(scope, receive, send, request_headers=headers)
  File "/home/pot/.conda/envs/tf_2.4.1_cpu/lib/python3.8/site-packages/starlette/middleware/cors.py", line 142, in simple_response
    await self.app(scope, receive, send)
  File "/home/pot/.conda/envs/tf_2.4.1_cpu/lib/python3.8/site-packages/starlette/exceptions.py", line 82, in __call__
    raise exc from None
  File "/home/pot/.conda/envs/tf_2.4.1_cpu/lib/python3.8/site-packages/starlette/exceptions.py", line 71, in __call__
    await self.app(scope, receive, sender)
  File "/home/pot/.conda/envs/tf_2.4.1_cpu/lib/python3.8/site-packages/starlette/routing.py", line 566, in __call__
    await route.handle(scope, receive, send)
  File "/home/pot/.conda/envs/tf_2.4.1_cpu/lib/python3.8/site-packages/starlette/routing.py", line 227, in handle
    await self.app(scope, receive, send)
  File "/home/pot/.conda/envs/tf_2.4.1_cpu/lib/python3.8/site-packages/starlette/routing.py", line 41, in app
    response = await func(request)
  File "/home/pot/.conda/envs/tf_2.4.1_cpu/lib/python3.8/site-packages/fastapi/routing.py", line 201, in app
    raw_response = await run_endpoint_function(
  File "/home/pot/.conda/envs/tf_2.4.1_cpu/lib/python3.8/site-packages/fastapi/routing.py", line 150, in run_endpoint_function
    return await run_in_threadpool(dependant.call, **values)
  File "/home/pot/.conda/envs/tf_2.4.1_cpu/lib/python3.8/site-packages/starlette/concurrency.py", line 34, in run_in_threadpool
    return await loop.run_in_executor(None, func, *args)
  File "/home/pot/.conda/envs/tf_2.4.1_cpu/lib/python3.8/concurrent/futures/thread.py", line 57, in run
    result = self.fn(*self.args, **self.kwargs)
  File "/home/pot/project/web-service/backend/app/api/resources/workflow_v1.py", line 31, in get_identity_card_by_day
    return data[0].name
IndexError: list index out of range
2021-04-22 18:14:18,272 - INFO - Shutting down
2021-04-22 18:14:18,373 - INFO - Waiting for application shutdown.
2021-04-22 18:14:18,373 - INFO - Application shutdown complete.
2021-04-22 18:14:18,373 - INFO - Finished server process [13416]
2021-04-22 18:14:18,401 - ERROR - Exception during reset or similar
Traceback (most recent call last):
  File "/home/pot/.conda/envs/tf_2.4.1_cpu/lib/python3.8/site-packages/sqlalchemy/pool/base.py", line 670, in _finalize_fairy
    fairy._reset(pool)
  File "/home/pot/.conda/envs/tf_2.4.1_cpu/lib/python3.8/site-packages/sqlalchemy/pool/base.py", line 875, in _reset
    pool._dialect.do_rollback(self)
  File "/home/pot/.conda/envs/tf_2.4.1_cpu/lib/python3.8/site-packages/sqlalchemy/engine/default.py", line 666, in do_rollback
    dbapi_connection.rollback()
sqlite3.ProgrammingError: SQLite objects created in a thread can only be used in that same thread. The object was created in thread id 140588986468096 and this is thread id 140589046826816.
2021-04-22 18:14:18,402 - ERROR - Exception closing connection <sqlite3.Connection object at 0x7fdd6cc7cc60>
Traceback (most recent call last):
  File "/home/pot/.conda/envs/tf_2.4.1_cpu/lib/python3.8/site-packages/sqlalchemy/pool/base.py", line 670, in _finalize_fairy
    fairy._reset(pool)
  File "/home/pot/.conda/envs/tf_2.4.1_cpu/lib/python3.8/site-packages/sqlalchemy/pool/base.py", line 875, in _reset
    pool._dialect.do_rollback(self)
  File "/home/pot/.conda/envs/tf_2.4.1_cpu/lib/python3.8/site-packages/sqlalchemy/engine/default.py", line 666, in do_rollback
    dbapi_connection.rollback()
sqlite3.ProgrammingError: SQLite objects created in a thread can only be used in that same thread. The object was created in thread id 140588986468096 and this is thread id 140589046826816.

During handling of the above exception, another exception occurred:

Traceback (most recent call last):
  File "/home/pot/.conda/envs/tf_2.4.1_cpu/lib/python3.8/site-packages/sqlalchemy/pool/base.py", line 238, in _close_connection
    self._dialect.do_close(connection)
  File "/home/pot/.conda/envs/tf_2.4.1_cpu/lib/python3.8/site-packages/sqlalchemy/engine/default.py", line 672, in do_close
    dbapi_connection.close()
sqlite3.ProgrammingError: SQLite objects created in a thread can only be used in that same thread. The object was created in thread id 140588986468096 and this is thread id 140589046826816.
2021-04-22 18:14:19,724 - INFO - Started server process [13419]
2021-04-22 18:14:19,724 - INFO - Waiting for application startup.
2021-04-22 18:14:19,724 - INFO - Application startup complete.
2021-04-22 18:14:19,724 - INFO - Uvicorn running on http://0.0.0.0:8081 (Press CTRL+C to quit)
2021-04-22 18:14:20,740 - INFO - BEGIN (implicit)
2021-04-22 18:14:20,750 - INFO - SELECT document.id AS document_id, document.name AS document_name, document.url AS document_url, document.export_date AS document_export_date, document.create_date AS document_create_date, document.update_date AS document_update_date, document.type_id AS document_type_id, document.status_id AS document_status_id, document_type_1.id AS document_type_1_id, document_type_1.name AS document_type_1_name, document_type_1.description AS document_type_1_description, document_type_1.create_date AS document_type_1_create_date, document_type_1.update_date AS document_type_1_update_date, status_1.id AS status_1_id, status_1.status_code AS status_1_status_code, status_1.status_name AS status_1_status_name, status_1.description AS status_1_description, status_1.create_date AS status_1_create_date, status_1.update_date AS status_1_update_date, document_split_1.id AS document_split_1_id, document_split_1.name AS document_split_1_name, document_split_1.value AS document_split_1_value, document_split_1.is_extracted AS document_split_1_is_extracted, document_split_1.url AS document_split_1_url, document_split_1.create_date AS document_split_1_create_date, document_split_1.update_date AS document_split_1_update_date, document_split_1.type_id AS document_split_1_type_id, document_split_1.document_id AS document_split_1_document_id 
FROM document LEFT OUTER JOIN document_type AS document_type_1 ON document_type_1.id = document.type_id LEFT OUTER JOIN status AS status_1 ON status_1.id = document.status_id LEFT OUTER JOIN document_split AS document_split_1 ON document.id = document_split_1.document_id 
WHERE document.type_id = ? AND document.status_id = ? AND document.export_date = ? ORDER BY document.export_date DESC
2021-04-22 18:14:20,751 - INFO - [generated in 0.00084s] ('1', 3, '2021-04-22')
2021-04-22 18:14:20,754 - INFO - ROLLBACK
2021-04-22 18:14:20,755 - ERROR - Exception in ASGI application
Traceback (most recent call last):
  File "/home/pot/.conda/envs/tf_2.4.1_cpu/lib/python3.8/site-packages/uvicorn/protocols/http/h11_impl.py", line 396, in run_asgi
    result = await app(self.scope, self.receive, self.send)
  File "/home/pot/.conda/envs/tf_2.4.1_cpu/lib/python3.8/site-packages/uvicorn/middleware/proxy_headers.py", line 45, in __call__
    return await self.app(scope, receive, send)
  File "/home/pot/.conda/envs/tf_2.4.1_cpu/lib/python3.8/site-packages/uvicorn/middleware/debug.py", line 81, in __call__
    raise exc from None
  File "/home/pot/.conda/envs/tf_2.4.1_cpu/lib/python3.8/site-packages/uvicorn/middleware/debug.py", line 78, in __call__
    await self.app(scope, receive, inner_send)
  File "/home/pot/.conda/envs/tf_2.4.1_cpu/lib/python3.8/site-packages/fastapi/applications.py", line 199, in __call__
    await super().__call__(scope, receive, send)
  File "/home/pot/.conda/envs/tf_2.4.1_cpu/lib/python3.8/site-packages/starlette/applications.py", line 111, in __call__
    await self.middleware_stack(scope, receive, send)
  File "/home/pot/.conda/envs/tf_2.4.1_cpu/lib/python3.8/site-packages/starlette/middleware/errors.py", line 181, in __call__
    raise exc from None
  File "/home/pot/.conda/envs/tf_2.4.1_cpu/lib/python3.8/site-packages/starlette/middleware/errors.py", line 159, in __call__
    await self.app(scope, receive, _send)
  File "/home/pot/.conda/envs/tf_2.4.1_cpu/lib/python3.8/site-packages/starlette/middleware/base.py", line 25, in __call__
    response = await self.dispatch_func(request, self.call_next)
  File "main.py", line 44, in db_session_middleware
    request.state.db.close()
  File "/home/pot/.conda/envs/tf_2.4.1_cpu/lib/python3.8/site-packages/sqlalchemy/orm/session.py", line 1723, in close
    self._close_impl(invalidate=False)
  File "/home/pot/.conda/envs/tf_2.4.1_cpu/lib/python3.8/site-packages/sqlalchemy/orm/session.py", line 1765, in _close_impl
    transaction.close(invalidate)
  File "/home/pot/.conda/envs/tf_2.4.1_cpu/lib/python3.8/site-packages/sqlalchemy/orm/session.py", line 923, in close
    transaction.close()
  File "/home/pot/.conda/envs/tf_2.4.1_cpu/lib/python3.8/site-packages/sqlalchemy/engine/base.py", line 2221, in close
    self._do_close()
  File "/home/pot/.conda/envs/tf_2.4.1_cpu/lib/python3.8/site-packages/sqlalchemy/engine/base.py", line 2430, in _do_close
    self._close_impl()
  File "/home/pot/.conda/envs/tf_2.4.1_cpu/lib/python3.8/site-packages/sqlalchemy/engine/base.py", line 2416, in _close_impl
    self._connection_rollback_impl()
  File "/home/pot/.conda/envs/tf_2.4.1_cpu/lib/python3.8/site-packages/sqlalchemy/engine/base.py", line 2408, in _connection_rollback_impl
    self.connection._rollback_impl()
  File "/home/pot/.conda/envs/tf_2.4.1_cpu/lib/python3.8/site-packages/sqlalchemy/engine/base.py", line 898, in _rollback_impl
    self._handle_dbapi_exception(e, None, None, None, None)
  File "/home/pot/.conda/envs/tf_2.4.1_cpu/lib/python3.8/site-packages/sqlalchemy/engine/base.py", line 1929, in _handle_dbapi_exception
    util.raise_(
  File "/home/pot/.conda/envs/tf_2.4.1_cpu/lib/python3.8/site-packages/sqlalchemy/util/compat.py", line 211, in raise_
    raise exception
  File "/home/pot/.conda/envs/tf_2.4.1_cpu/lib/python3.8/site-packages/sqlalchemy/engine/base.py", line 896, in _rollback_impl
    self.engine.dialect.do_rollback(self.connection)
  File "/home/pot/.conda/envs/tf_2.4.1_cpu/lib/python3.8/site-packages/sqlalchemy/engine/default.py", line 666, in do_rollback
    dbapi_connection.rollback()
sqlalchemy.exc.ProgrammingError: (sqlite3.ProgrammingError) SQLite objects created in a thread can only be used in that same thread. The object was created in thread id 140281617463040 and this is thread id 140281677821760.
(Background on this error at: http://sqlalche.me/e/14/f405)
2021-04-22 18:14:21,806 - INFO - BEGIN (implicit)
2021-04-22 18:14:21,806 - INFO - SELECT document.id AS document_id, document.name AS document_name, document.url AS document_url, document.export_date AS document_export_date, document.create_date AS document_create_date, document.update_date AS document_update_date, document.type_id AS document_type_id, document.status_id AS document_status_id, document_type_1.id AS document_type_1_id, document_type_1.name AS document_type_1_name, document_type_1.description AS document_type_1_description, document_type_1.create_date AS document_type_1_create_date, document_type_1.update_date AS document_type_1_update_date, status_1.id AS status_1_id, status_1.status_code AS status_1_status_code, status_1.status_name AS status_1_status_name, status_1.description AS status_1_description, status_1.create_date AS status_1_create_date, status_1.update_date AS status_1_update_date, document_split_1.id AS document_split_1_id, document_split_1.name AS document_split_1_name, document_split_1.value AS document_split_1_value, document_split_1.is_extracted AS document_split_1_is_extracted, document_split_1.url AS document_split_1_url, document_split_1.create_date AS document_split_1_create_date, document_split_1.update_date AS document_split_1_update_date, document_split_1.type_id AS document_split_1_type_id, document_split_1.document_id AS document_split_1_document_id 
FROM document LEFT OUTER JOIN document_type AS document_type_1 ON document_type_1.id = document.type_id LEFT OUTER JOIN status AS status_1 ON status_1.id = document.status_id LEFT OUTER JOIN document_split AS document_split_1 ON document.id = document_split_1.document_id 
WHERE document.type_id = ? AND document.status_id = ? AND document.export_date = ? ORDER BY document.export_date DESC
2021-04-22 18:14:21,807 - INFO - [cached since 1.056s ago] ('1', 3, '2021-04-22')
2021-04-22 18:14:21,808 - INFO - ROLLBACK
2021-04-22 18:14:21,809 - ERROR - Exception in ASGI application
Traceback (most recent call last):
  File "/home/pot/.conda/envs/tf_2.4.1_cpu/lib/python3.8/site-packages/uvicorn/protocols/http/h11_impl.py", line 396, in run_asgi
    result = await app(self.scope, self.receive, self.send)
  File "/home/pot/.conda/envs/tf_2.4.1_cpu/lib/python3.8/site-packages/uvicorn/middleware/proxy_headers.py", line 45, in __call__
    return await self.app(scope, receive, send)
  File "/home/pot/.conda/envs/tf_2.4.1_cpu/lib/python3.8/site-packages/uvicorn/middleware/debug.py", line 81, in __call__
    raise exc from None
  File "/home/pot/.conda/envs/tf_2.4.1_cpu/lib/python3.8/site-packages/uvicorn/middleware/debug.py", line 78, in __call__
    await self.app(scope, receive, inner_send)
  File "/home/pot/.conda/envs/tf_2.4.1_cpu/lib/python3.8/site-packages/fastapi/applications.py", line 199, in __call__
    await super().__call__(scope, receive, send)
  File "/home/pot/.conda/envs/tf_2.4.1_cpu/lib/python3.8/site-packages/starlette/applications.py", line 111, in __call__
    await self.middleware_stack(scope, receive, send)
  File "/home/pot/.conda/envs/tf_2.4.1_cpu/lib/python3.8/site-packages/starlette/middleware/errors.py", line 181, in __call__
    raise exc from None
  File "/home/pot/.conda/envs/tf_2.4.1_cpu/lib/python3.8/site-packages/starlette/middleware/errors.py", line 159, in __call__
    await self.app(scope, receive, _send)
  File "/home/pot/.conda/envs/tf_2.4.1_cpu/lib/python3.8/site-packages/starlette/middleware/base.py", line 25, in __call__
    response = await self.dispatch_func(request, self.call_next)
  File "main.py", line 44, in db_session_middleware
    request.state.db.close()
  File "/home/pot/.conda/envs/tf_2.4.1_cpu/lib/python3.8/site-packages/sqlalchemy/orm/session.py", line 1723, in close
    self._close_impl(invalidate=False)
  File "/home/pot/.conda/envs/tf_2.4.1_cpu/lib/python3.8/site-packages/sqlalchemy/orm/session.py", line 1765, in _close_impl
    transaction.close(invalidate)
  File "/home/pot/.conda/envs/tf_2.4.1_cpu/lib/python3.8/site-packages/sqlalchemy/orm/session.py", line 923, in close
    transaction.close()
  File "/home/pot/.conda/envs/tf_2.4.1_cpu/lib/python3.8/site-packages/sqlalchemy/engine/base.py", line 2221, in close
    self._do_close()
  File "/home/pot/.conda/envs/tf_2.4.1_cpu/lib/python3.8/site-packages/sqlalchemy/engine/base.py", line 2430, in _do_close
    self._close_impl()
  File "/home/pot/.conda/envs/tf_2.4.1_cpu/lib/python3.8/site-packages/sqlalchemy/engine/base.py", line 2416, in _close_impl
    self._connection_rollback_impl()
  File "/home/pot/.conda/envs/tf_2.4.1_cpu/lib/python3.8/site-packages/sqlalchemy/engine/base.py", line 2408, in _connection_rollback_impl
    self.connection._rollback_impl()
  File "/home/pot/.conda/envs/tf_2.4.1_cpu/lib/python3.8/site-packages/sqlalchemy/engine/base.py", line 898, in _rollback_impl
    self._handle_dbapi_exception(e, None, None, None, None)
  File "/home/pot/.conda/envs/tf_2.4.1_cpu/lib/python3.8/site-packages/sqlalchemy/engine/base.py", line 1929, in _handle_dbapi_exception
    util.raise_(
  File "/home/pot/.conda/envs/tf_2.4.1_cpu/lib/python3.8/site-packages/sqlalchemy/util/compat.py", line 211, in raise_
    raise exception
  File "/home/pot/.conda/envs/tf_2.4.1_cpu/lib/python3.8/site-packages/sqlalchemy/engine/base.py", line 896, in _rollback_impl
    self.engine.dialect.do_rollback(self.connection)
  File "/home/pot/.conda/envs/tf_2.4.1_cpu/lib/python3.8/site-packages/sqlalchemy/engine/default.py", line 666, in do_rollback
    dbapi_connection.rollback()
sqlalchemy.exc.ProgrammingError: (sqlite3.ProgrammingError) SQLite objects created in a thread can only be used in that same thread. The object was created in thread id 140281617463040 and this is thread id 140281677821760.
(Background on this error at: http://sqlalche.me/e/14/f405)
2021-04-22 18:15:13,928 - INFO - Shutting down
2021-04-22 18:15:14,028 - INFO - Waiting for application shutdown.
2021-04-22 18:15:14,029 - INFO - Application shutdown complete.
2021-04-22 18:15:14,029 - INFO - Finished server process [13419]
2021-04-22 18:15:14,059 - ERROR - Exception during reset or similar
Traceback (most recent call last):
  File "/home/pot/.conda/envs/tf_2.4.1_cpu/lib/python3.8/site-packages/sqlalchemy/pool/base.py", line 670, in _finalize_fairy
    fairy._reset(pool)
  File "/home/pot/.conda/envs/tf_2.4.1_cpu/lib/python3.8/site-packages/sqlalchemy/pool/base.py", line 875, in _reset
    pool._dialect.do_rollback(self)
  File "/home/pot/.conda/envs/tf_2.4.1_cpu/lib/python3.8/site-packages/sqlalchemy/engine/default.py", line 666, in do_rollback
    dbapi_connection.rollback()
sqlite3.ProgrammingError: SQLite objects created in a thread can only be used in that same thread. The object was created in thread id 140281617463040 and this is thread id 140281677821760.
2021-04-22 18:15:14,060 - ERROR - Exception closing connection <sqlite3.Connection object at 0x7f95db656030>
Traceback (most recent call last):
  File "/home/pot/.conda/envs/tf_2.4.1_cpu/lib/python3.8/site-packages/sqlalchemy/pool/base.py", line 670, in _finalize_fairy
    fairy._reset(pool)
  File "/home/pot/.conda/envs/tf_2.4.1_cpu/lib/python3.8/site-packages/sqlalchemy/pool/base.py", line 875, in _reset
    pool._dialect.do_rollback(self)
  File "/home/pot/.conda/envs/tf_2.4.1_cpu/lib/python3.8/site-packages/sqlalchemy/engine/default.py", line 666, in do_rollback
    dbapi_connection.rollback()
sqlite3.ProgrammingError: SQLite objects created in a thread can only be used in that same thread. The object was created in thread id 140281617463040 and this is thread id 140281677821760.

During handling of the above exception, another exception occurred:

Traceback (most recent call last):
  File "/home/pot/.conda/envs/tf_2.4.1_cpu/lib/python3.8/site-packages/sqlalchemy/pool/base.py", line 238, in _close_connection
    self._dialect.do_close(connection)
  File "/home/pot/.conda/envs/tf_2.4.1_cpu/lib/python3.8/site-packages/sqlalchemy/engine/default.py", line 672, in do_close
    dbapi_connection.close()
sqlite3.ProgrammingError: SQLite objects created in a thread can only be used in that same thread. The object was created in thread id 140281617463040 and this is thread id 140281677821760.
2021-04-22 18:15:14,060 - ERROR - Exception during reset or similar
Traceback (most recent call last):
  File "/home/pot/.conda/envs/tf_2.4.1_cpu/lib/python3.8/site-packages/sqlalchemy/pool/base.py", line 670, in _finalize_fairy
    fairy._reset(pool)
  File "/home/pot/.conda/envs/tf_2.4.1_cpu/lib/python3.8/site-packages/sqlalchemy/pool/base.py", line 875, in _reset
    pool._dialect.do_rollback(self)
  File "/home/pot/.conda/envs/tf_2.4.1_cpu/lib/python3.8/site-packages/sqlalchemy/engine/default.py", line 666, in do_rollback
    dbapi_connection.rollback()
sqlite3.ProgrammingError: SQLite objects created in a thread can only be used in that same thread. The object was created in thread id 140281617463040 and this is thread id 140281677821760.
2021-04-22 18:15:14,060 - ERROR - Exception closing connection <sqlite3.Connection object at 0x7f95dc28fc60>
Traceback (most recent call last):
  File "/home/pot/.conda/envs/tf_2.4.1_cpu/lib/python3.8/site-packages/sqlalchemy/pool/base.py", line 670, in _finalize_fairy
    fairy._reset(pool)
  File "/home/pot/.conda/envs/tf_2.4.1_cpu/lib/python3.8/site-packages/sqlalchemy/pool/base.py", line 875, in _reset
    pool._dialect.do_rollback(self)
  File "/home/pot/.conda/envs/tf_2.4.1_cpu/lib/python3.8/site-packages/sqlalchemy/engine/default.py", line 666, in do_rollback
    dbapi_connection.rollback()
sqlite3.ProgrammingError: SQLite objects created in a thread can only be used in that same thread. The object was created in thread id 140281617463040 and this is thread id 140281677821760.

During handling of the above exception, another exception occurred:

Traceback (most recent call last):
  File "/home/pot/.conda/envs/tf_2.4.1_cpu/lib/python3.8/site-packages/sqlalchemy/pool/base.py", line 238, in _close_connection
    self._dialect.do_close(connection)
  File "/home/pot/.conda/envs/tf_2.4.1_cpu/lib/python3.8/site-packages/sqlalchemy/engine/default.py", line 672, in do_close
    dbapi_connection.close()
sqlite3.ProgrammingError: SQLite objects created in a thread can only be used in that same thread. The object was created in thread id 140281617463040 and this is thread id 140281677821760.
2021-04-22 18:15:54,587 - INFO - Started server process [13427]
2021-04-22 18:15:54,588 - INFO - Waiting for application startup.
2021-04-22 18:15:54,588 - INFO - Application startup complete.
2021-04-22 18:15:54,588 - INFO - Uvicorn running on http://0.0.0.0:8081 (Press CTRL+C to quit)
2021-04-22 18:15:57,089 - INFO - BEGIN (implicit)
2021-04-22 18:15:57,097 - INFO - SELECT document.id AS document_id, document.name AS document_name, document.url AS document_url, document.export_date AS document_export_date, document.create_date AS document_create_date, document.update_date AS document_update_date, document.type_id AS document_type_id, document.status_id AS document_status_id, document_type_1.id AS document_type_1_id, document_type_1.name AS document_type_1_name, document_type_1.description AS document_type_1_description, document_type_1.create_date AS document_type_1_create_date, document_type_1.update_date AS document_type_1_update_date, status_1.id AS status_1_id, status_1.status_code AS status_1_status_code, status_1.status_name AS status_1_status_name, status_1.description AS status_1_description, status_1.create_date AS status_1_create_date, status_1.update_date AS status_1_update_date, document_split_1.id AS document_split_1_id, document_split_1.name AS document_split_1_name, document_split_1.value AS document_split_1_value, document_split_1.is_extracted AS document_split_1_is_extracted, document_split_1.url AS document_split_1_url, document_split_1.create_date AS document_split_1_create_date, document_split_1.update_date AS document_split_1_update_date, document_split_1.type_id AS document_split_1_type_id, document_split_1.document_id AS document_split_1_document_id 
FROM document LEFT OUTER JOIN document_type AS document_type_1 ON document_type_1.id = document.type_id LEFT OUTER JOIN status AS status_1 ON status_1.id = document.status_id LEFT OUTER JOIN document_split AS document_split_1 ON document.id = document_split_1.document_id 
WHERE document.type_id = ? AND document.status_id = ? AND document.export_date = ? ORDER BY document.export_date DESC
2021-04-22 18:15:57,098 - INFO - [generated in 0.00084s] ('1', 3, '2021-04-22')
2021-04-22 18:15:57,100 - ERROR - Exception in ASGI application
Traceback (most recent call last):
  File "/home/pot/.conda/envs/tf_2.4.1_cpu/lib/python3.8/site-packages/uvicorn/protocols/http/h11_impl.py", line 396, in run_asgi
    result = await app(self.scope, self.receive, self.send)
  File "/home/pot/.conda/envs/tf_2.4.1_cpu/lib/python3.8/site-packages/uvicorn/middleware/proxy_headers.py", line 45, in __call__
    return await self.app(scope, receive, send)
  File "/home/pot/.conda/envs/tf_2.4.1_cpu/lib/python3.8/site-packages/uvicorn/middleware/debug.py", line 81, in __call__
    raise exc from None
  File "/home/pot/.conda/envs/tf_2.4.1_cpu/lib/python3.8/site-packages/uvicorn/middleware/debug.py", line 78, in __call__
    await self.app(scope, receive, inner_send)
  File "/home/pot/.conda/envs/tf_2.4.1_cpu/lib/python3.8/site-packages/fastapi/applications.py", line 199, in __call__
    await super().__call__(scope, receive, send)
  File "/home/pot/.conda/envs/tf_2.4.1_cpu/lib/python3.8/site-packages/starlette/applications.py", line 111, in __call__
    await self.middleware_stack(scope, receive, send)
  File "/home/pot/.conda/envs/tf_2.4.1_cpu/lib/python3.8/site-packages/starlette/middleware/errors.py", line 181, in __call__
    raise exc from None
  File "/home/pot/.conda/envs/tf_2.4.1_cpu/lib/python3.8/site-packages/starlette/middleware/errors.py", line 159, in __call__
    await self.app(scope, receive, _send)
  File "/home/pot/.conda/envs/tf_2.4.1_cpu/lib/python3.8/site-packages/starlette/middleware/base.py", line 25, in __call__
    response = await self.dispatch_func(request, self.call_next)
  File "main.py", line 43, in db_session_middleware
    response = await call_next(request)
  File "/home/pot/.conda/envs/tf_2.4.1_cpu/lib/python3.8/site-packages/starlette/middleware/base.py", line 45, in call_next
    task.result()
  File "/home/pot/.conda/envs/tf_2.4.1_cpu/lib/python3.8/site-packages/starlette/middleware/base.py", line 38, in coro
    await self.app(scope, receive, send)
  File "/home/pot/.conda/envs/tf_2.4.1_cpu/lib/python3.8/site-packages/starlette/middleware/cors.py", line 86, in __call__
    await self.simple_response(scope, receive, send, request_headers=headers)
  File "/home/pot/.conda/envs/tf_2.4.1_cpu/lib/python3.8/site-packages/starlette/middleware/cors.py", line 142, in simple_response
    await self.app(scope, receive, send)
  File "/home/pot/.conda/envs/tf_2.4.1_cpu/lib/python3.8/site-packages/starlette/exceptions.py", line 82, in __call__
    raise exc from None
  File "/home/pot/.conda/envs/tf_2.4.1_cpu/lib/python3.8/site-packages/starlette/exceptions.py", line 71, in __call__
    await self.app(scope, receive, sender)
  File "/home/pot/.conda/envs/tf_2.4.1_cpu/lib/python3.8/site-packages/starlette/routing.py", line 566, in __call__
    await route.handle(scope, receive, send)
  File "/home/pot/.conda/envs/tf_2.4.1_cpu/lib/python3.8/site-packages/starlette/routing.py", line 227, in handle
    await self.app(scope, receive, send)
  File "/home/pot/.conda/envs/tf_2.4.1_cpu/lib/python3.8/site-packages/starlette/routing.py", line 41, in app
    response = await func(request)
  File "/home/pot/.conda/envs/tf_2.4.1_cpu/lib/python3.8/site-packages/fastapi/routing.py", line 201, in app
    raw_response = await run_endpoint_function(
  File "/home/pot/.conda/envs/tf_2.4.1_cpu/lib/python3.8/site-packages/fastapi/routing.py", line 150, in run_endpoint_function
    return await run_in_threadpool(dependant.call, **values)
  File "/home/pot/.conda/envs/tf_2.4.1_cpu/lib/python3.8/site-packages/starlette/concurrency.py", line 34, in run_in_threadpool
    return await loop.run_in_executor(None, func, *args)
  File "/home/pot/.conda/envs/tf_2.4.1_cpu/lib/python3.8/concurrent/futures/thread.py", line 57, in run
    result = self.fn(*self.args, **self.kwargs)
  File "/home/pot/project/web-service/backend/app/api/resources/workflow_v1.py", line 31, in get_identity_card_by_day
    return data.name
AttributeError: 'list' object has no attribute 'name'
2021-04-22 18:16:22,486 - INFO - Shutting down
2021-04-22 18:16:22,587 - INFO - Finished server process [13427]
2021-04-22 18:16:22,617 - ERROR - Exception during reset or similar
Traceback (most recent call last):
  File "/home/pot/.conda/envs/tf_2.4.1_cpu/lib/python3.8/site-packages/sqlalchemy/pool/base.py", line 670, in _finalize_fairy
    fairy._reset(pool)
  File "/home/pot/.conda/envs/tf_2.4.1_cpu/lib/python3.8/site-packages/sqlalchemy/pool/base.py", line 875, in _reset
    pool._dialect.do_rollback(self)
  File "/home/pot/.conda/envs/tf_2.4.1_cpu/lib/python3.8/site-packages/sqlalchemy/engine/default.py", line 666, in do_rollback
    dbapi_connection.rollback()
sqlite3.ProgrammingError: SQLite objects created in a thread can only be used in that same thread. The object was created in thread id 140608562157312 and this is thread id 140608622516032.
2021-04-22 18:16:22,618 - ERROR - Exception closing connection <sqlite3.Connection object at 0x7fe1fb952c60>
Traceback (most recent call last):
  File "/home/pot/.conda/envs/tf_2.4.1_cpu/lib/python3.8/site-packages/sqlalchemy/pool/base.py", line 670, in _finalize_fairy
    fairy._reset(pool)
  File "/home/pot/.conda/envs/tf_2.4.1_cpu/lib/python3.8/site-packages/sqlalchemy/pool/base.py", line 875, in _reset
    pool._dialect.do_rollback(self)
  File "/home/pot/.conda/envs/tf_2.4.1_cpu/lib/python3.8/site-packages/sqlalchemy/engine/default.py", line 666, in do_rollback
    dbapi_connection.rollback()
sqlite3.ProgrammingError: SQLite objects created in a thread can only be used in that same thread. The object was created in thread id 140608562157312 and this is thread id 140608622516032.

During handling of the above exception, another exception occurred:

Traceback (most recent call last):
  File "/home/pot/.conda/envs/tf_2.4.1_cpu/lib/python3.8/site-packages/sqlalchemy/pool/base.py", line 238, in _close_connection
    self._dialect.do_close(connection)
  File "/home/pot/.conda/envs/tf_2.4.1_cpu/lib/python3.8/site-packages/sqlalchemy/engine/default.py", line 672, in do_close
    dbapi_connection.close()
sqlite3.ProgrammingError: SQLite objects created in a thread can only be used in that same thread. The object was created in thread id 140608562157312 and this is thread id 140608622516032.
2021-04-22 18:16:24,216 - INFO - Started server process [13430]
2021-04-22 18:16:24,216 - INFO - Waiting for application startup.
2021-04-22 18:16:24,217 - INFO - Application startup complete.
2021-04-22 18:16:24,217 - INFO - Uvicorn running on http://0.0.0.0:8081 (Press CTRL+C to quit)
2021-04-22 18:16:25,763 - INFO - BEGIN (implicit)
2021-04-22 18:16:25,772 - INFO - SELECT document.id AS document_id, document.name AS document_name, document.url AS document_url, document.export_date AS document_export_date, document.create_date AS document_create_date, document.update_date AS document_update_date, document.type_id AS document_type_id, document.status_id AS document_status_id, document_type_1.id AS document_type_1_id, document_type_1.name AS document_type_1_name, document_type_1.description AS document_type_1_description, document_type_1.create_date AS document_type_1_create_date, document_type_1.update_date AS document_type_1_update_date, status_1.id AS status_1_id, status_1.status_code AS status_1_status_code, status_1.status_name AS status_1_status_name, status_1.description AS status_1_description, status_1.create_date AS status_1_create_date, status_1.update_date AS status_1_update_date, document_split_1.id AS document_split_1_id, document_split_1.name AS document_split_1_name, document_split_1.value AS document_split_1_value, document_split_1.is_extracted AS document_split_1_is_extracted, document_split_1.url AS document_split_1_url, document_split_1.create_date AS document_split_1_create_date, document_split_1.update_date AS document_split_1_update_date, document_split_1.type_id AS document_split_1_type_id, document_split_1.document_id AS document_split_1_document_id 
FROM document LEFT OUTER JOIN document_type AS document_type_1 ON document_type_1.id = document.type_id LEFT OUTER JOIN status AS status_1 ON status_1.id = document.status_id LEFT OUTER JOIN document_split AS document_split_1 ON document.id = document_split_1.document_id 
WHERE document.type_id = ? AND document.status_id = ? AND document.export_date = ? ORDER BY document.export_date DESC
2021-04-22 18:16:25,773 - INFO - [generated in 0.00043s] ('1', 3, '2021-04-22')
2021-04-22 18:16:25,775 - INFO - ROLLBACK
2021-04-22 18:16:25,775 - ERROR - Exception in ASGI application
Traceback (most recent call last):
  File "/home/pot/.conda/envs/tf_2.4.1_cpu/lib/python3.8/site-packages/uvicorn/protocols/http/h11_impl.py", line 396, in run_asgi
    result = await app(self.scope, self.receive, self.send)
  File "/home/pot/.conda/envs/tf_2.4.1_cpu/lib/python3.8/site-packages/uvicorn/middleware/proxy_headers.py", line 45, in __call__
    return await self.app(scope, receive, send)
  File "/home/pot/.conda/envs/tf_2.4.1_cpu/lib/python3.8/site-packages/uvicorn/middleware/debug.py", line 81, in __call__
    raise exc from None
  File "/home/pot/.conda/envs/tf_2.4.1_cpu/lib/python3.8/site-packages/uvicorn/middleware/debug.py", line 78, in __call__
    await self.app(scope, receive, inner_send)
  File "/home/pot/.conda/envs/tf_2.4.1_cpu/lib/python3.8/site-packages/fastapi/applications.py", line 199, in __call__
    await super().__call__(scope, receive, send)
  File "/home/pot/.conda/envs/tf_2.4.1_cpu/lib/python3.8/site-packages/starlette/applications.py", line 111, in __call__
    await self.middleware_stack(scope, receive, send)
  File "/home/pot/.conda/envs/tf_2.4.1_cpu/lib/python3.8/site-packages/starlette/middleware/errors.py", line 181, in __call__
    raise exc from None
  File "/home/pot/.conda/envs/tf_2.4.1_cpu/lib/python3.8/site-packages/starlette/middleware/errors.py", line 159, in __call__
    await self.app(scope, receive, _send)
  File "/home/pot/.conda/envs/tf_2.4.1_cpu/lib/python3.8/site-packages/starlette/middleware/base.py", line 25, in __call__
    response = await self.dispatch_func(request, self.call_next)
  File "main.py", line 44, in db_session_middleware
    request.state.db.close()
  File "/home/pot/.conda/envs/tf_2.4.1_cpu/lib/python3.8/site-packages/sqlalchemy/orm/session.py", line 1723, in close
    self._close_impl(invalidate=False)
  File "/home/pot/.conda/envs/tf_2.4.1_cpu/lib/python3.8/site-packages/sqlalchemy/orm/session.py", line 1765, in _close_impl
    transaction.close(invalidate)
  File "/home/pot/.conda/envs/tf_2.4.1_cpu/lib/python3.8/site-packages/sqlalchemy/orm/session.py", line 923, in close
    transaction.close()
  File "/home/pot/.conda/envs/tf_2.4.1_cpu/lib/python3.8/site-packages/sqlalchemy/engine/base.py", line 2221, in close
    self._do_close()
  File "/home/pot/.conda/envs/tf_2.4.1_cpu/lib/python3.8/site-packages/sqlalchemy/engine/base.py", line 2430, in _do_close
    self._close_impl()
  File "/home/pot/.conda/envs/tf_2.4.1_cpu/lib/python3.8/site-packages/sqlalchemy/engine/base.py", line 2416, in _close_impl
    self._connection_rollback_impl()
  File "/home/pot/.conda/envs/tf_2.4.1_cpu/lib/python3.8/site-packages/sqlalchemy/engine/base.py", line 2408, in _connection_rollback_impl
    self.connection._rollback_impl()
  File "/home/pot/.conda/envs/tf_2.4.1_cpu/lib/python3.8/site-packages/sqlalchemy/engine/base.py", line 898, in _rollback_impl
    self._handle_dbapi_exception(e, None, None, None, None)
  File "/home/pot/.conda/envs/tf_2.4.1_cpu/lib/python3.8/site-packages/sqlalchemy/engine/base.py", line 1929, in _handle_dbapi_exception
    util.raise_(
  File "/home/pot/.conda/envs/tf_2.4.1_cpu/lib/python3.8/site-packages/sqlalchemy/util/compat.py", line 211, in raise_
    raise exception
  File "/home/pot/.conda/envs/tf_2.4.1_cpu/lib/python3.8/site-packages/sqlalchemy/engine/base.py", line 896, in _rollback_impl
    self.engine.dialect.do_rollback(self.connection)
  File "/home/pot/.conda/envs/tf_2.4.1_cpu/lib/python3.8/site-packages/sqlalchemy/engine/default.py", line 666, in do_rollback
    dbapi_connection.rollback()
sqlalchemy.exc.ProgrammingError: (sqlite3.ProgrammingError) SQLite objects created in a thread can only be used in that same thread. The object was created in thread id 139664453371648 and this is thread id 139664513730368.
(Background on this error at: http://sqlalche.me/e/14/f405)
2021-04-22 18:16:45,493 - INFO - Shutting down
2021-04-22 18:16:45,593 - INFO - Waiting for application shutdown.
2021-04-22 18:16:45,594 - INFO - Application shutdown complete.
2021-04-22 18:16:45,594 - INFO - Finished server process [13430]
2021-04-22 18:16:45,620 - ERROR - Exception during reset or similar
Traceback (most recent call last):
  File "/home/pot/.conda/envs/tf_2.4.1_cpu/lib/python3.8/site-packages/sqlalchemy/pool/base.py", line 670, in _finalize_fairy
    fairy._reset(pool)
  File "/home/pot/.conda/envs/tf_2.4.1_cpu/lib/python3.8/site-packages/sqlalchemy/pool/base.py", line 875, in _reset
    pool._dialect.do_rollback(self)
  File "/home/pot/.conda/envs/tf_2.4.1_cpu/lib/python3.8/site-packages/sqlalchemy/engine/default.py", line 666, in do_rollback
    dbapi_connection.rollback()
sqlite3.ProgrammingError: SQLite objects created in a thread can only be used in that same thread. The object was created in thread id 139664453371648 and this is thread id 139664513730368.
2021-04-22 18:16:45,620 - ERROR - Exception closing connection <sqlite3.Connection object at 0x7f062a505c60>
Traceback (most recent call last):
  File "/home/pot/.conda/envs/tf_2.4.1_cpu/lib/python3.8/site-packages/sqlalchemy/pool/base.py", line 670, in _finalize_fairy
    fairy._reset(pool)
  File "/home/pot/.conda/envs/tf_2.4.1_cpu/lib/python3.8/site-packages/sqlalchemy/pool/base.py", line 875, in _reset
    pool._dialect.do_rollback(self)
  File "/home/pot/.conda/envs/tf_2.4.1_cpu/lib/python3.8/site-packages/sqlalchemy/engine/default.py", line 666, in do_rollback
    dbapi_connection.rollback()
sqlite3.ProgrammingError: SQLite objects created in a thread can only be used in that same thread. The object was created in thread id 139664453371648 and this is thread id 139664513730368.

During handling of the above exception, another exception occurred:

Traceback (most recent call last):
  File "/home/pot/.conda/envs/tf_2.4.1_cpu/lib/python3.8/site-packages/sqlalchemy/pool/base.py", line 238, in _close_connection
    self._dialect.do_close(connection)
  File "/home/pot/.conda/envs/tf_2.4.1_cpu/lib/python3.8/site-packages/sqlalchemy/engine/default.py", line 672, in do_close
    dbapi_connection.close()
sqlite3.ProgrammingError: SQLite objects created in a thread can only be used in that same thread. The object was created in thread id 139664453371648 and this is thread id 139664513730368.
2021-04-22 18:16:46,792 - INFO - Started server process [13433]
2021-04-22 18:16:46,793 - INFO - Waiting for application startup.
2021-04-22 18:16:46,794 - INFO - Application startup complete.
2021-04-22 18:16:46,794 - INFO - Uvicorn running on http://0.0.0.0:8081 (Press CTRL+C to quit)
2021-04-22 18:16:47,937 - INFO - BEGIN (implicit)
2021-04-22 18:16:47,950 - INFO - SELECT document.id AS document_id, document.name AS document_name, document.url AS document_url, document.export_date AS document_export_date, document.create_date AS document_create_date, document.update_date AS document_update_date, document.type_id AS document_type_id, document.status_id AS document_status_id, document_type_1.id AS document_type_1_id, document_type_1.name AS document_type_1_name, document_type_1.description AS document_type_1_description, document_type_1.create_date AS document_type_1_create_date, document_type_1.update_date AS document_type_1_update_date, status_1.id AS status_1_id, status_1.status_code AS status_1_status_code, status_1.status_name AS status_1_status_name, status_1.description AS status_1_description, status_1.create_date AS status_1_create_date, status_1.update_date AS status_1_update_date, document_split_1.id AS document_split_1_id, document_split_1.name AS document_split_1_name, document_split_1.value AS document_split_1_value, document_split_1.is_extracted AS document_split_1_is_extracted, document_split_1.url AS document_split_1_url, document_split_1.create_date AS document_split_1_create_date, document_split_1.update_date AS document_split_1_update_date, document_split_1.type_id AS document_split_1_type_id, document_split_1.document_id AS document_split_1_document_id 
FROM document LEFT OUTER JOIN document_type AS document_type_1 ON document_type_1.id = document.type_id LEFT OUTER JOIN status AS status_1 ON status_1.id = document.status_id LEFT OUTER JOIN document_split AS document_split_1 ON document.id = document_split_1.document_id 
WHERE document.type_id = ? AND document.status_id = ? AND document.export_date = ? ORDER BY document.export_date DESC
2021-04-22 18:16:47,950 - INFO - [generated in 0.00052s] ('1', 3, '2021-04-22')
2021-04-22 18:16:47,953 - INFO - ROLLBACK
2021-04-22 18:16:47,954 - ERROR - Exception in ASGI application
Traceback (most recent call last):
  File "/home/pot/.conda/envs/tf_2.4.1_cpu/lib/python3.8/site-packages/uvicorn/protocols/http/h11_impl.py", line 396, in run_asgi
    result = await app(self.scope, self.receive, self.send)
  File "/home/pot/.conda/envs/tf_2.4.1_cpu/lib/python3.8/site-packages/uvicorn/middleware/proxy_headers.py", line 45, in __call__
    return await self.app(scope, receive, send)
  File "/home/pot/.conda/envs/tf_2.4.1_cpu/lib/python3.8/site-packages/uvicorn/middleware/debug.py", line 81, in __call__
    raise exc from None
  File "/home/pot/.conda/envs/tf_2.4.1_cpu/lib/python3.8/site-packages/uvicorn/middleware/debug.py", line 78, in __call__
    await self.app(scope, receive, inner_send)
  File "/home/pot/.conda/envs/tf_2.4.1_cpu/lib/python3.8/site-packages/fastapi/applications.py", line 199, in __call__
    await super().__call__(scope, receive, send)
  File "/home/pot/.conda/envs/tf_2.4.1_cpu/lib/python3.8/site-packages/starlette/applications.py", line 111, in __call__
    await self.middleware_stack(scope, receive, send)
  File "/home/pot/.conda/envs/tf_2.4.1_cpu/lib/python3.8/site-packages/starlette/middleware/errors.py", line 181, in __call__
    raise exc from None
  File "/home/pot/.conda/envs/tf_2.4.1_cpu/lib/python3.8/site-packages/starlette/middleware/errors.py", line 159, in __call__
    await self.app(scope, receive, _send)
  File "/home/pot/.conda/envs/tf_2.4.1_cpu/lib/python3.8/site-packages/starlette/middleware/base.py", line 25, in __call__
    response = await self.dispatch_func(request, self.call_next)
  File "main.py", line 44, in db_session_middleware
    request.state.db.close()
  File "/home/pot/.conda/envs/tf_2.4.1_cpu/lib/python3.8/site-packages/sqlalchemy/orm/session.py", line 1723, in close
    self._close_impl(invalidate=False)
  File "/home/pot/.conda/envs/tf_2.4.1_cpu/lib/python3.8/site-packages/sqlalchemy/orm/session.py", line 1765, in _close_impl
    transaction.close(invalidate)
  File "/home/pot/.conda/envs/tf_2.4.1_cpu/lib/python3.8/site-packages/sqlalchemy/orm/session.py", line 923, in close
    transaction.close()
  File "/home/pot/.conda/envs/tf_2.4.1_cpu/lib/python3.8/site-packages/sqlalchemy/engine/base.py", line 2221, in close
    self._do_close()
  File "/home/pot/.conda/envs/tf_2.4.1_cpu/lib/python3.8/site-packages/sqlalchemy/engine/base.py", line 2430, in _do_close
    self._close_impl()
  File "/home/pot/.conda/envs/tf_2.4.1_cpu/lib/python3.8/site-packages/sqlalchemy/engine/base.py", line 2416, in _close_impl
    self._connection_rollback_impl()
  File "/home/pot/.conda/envs/tf_2.4.1_cpu/lib/python3.8/site-packages/sqlalchemy/engine/base.py", line 2408, in _connection_rollback_impl
    self.connection._rollback_impl()
  File "/home/pot/.conda/envs/tf_2.4.1_cpu/lib/python3.8/site-packages/sqlalchemy/engine/base.py", line 898, in _rollback_impl
    self._handle_dbapi_exception(e, None, None, None, None)
  File "/home/pot/.conda/envs/tf_2.4.1_cpu/lib/python3.8/site-packages/sqlalchemy/engine/base.py", line 1929, in _handle_dbapi_exception
    util.raise_(
  File "/home/pot/.conda/envs/tf_2.4.1_cpu/lib/python3.8/site-packages/sqlalchemy/util/compat.py", line 211, in raise_
    raise exception
  File "/home/pot/.conda/envs/tf_2.4.1_cpu/lib/python3.8/site-packages/sqlalchemy/engine/base.py", line 896, in _rollback_impl
    self.engine.dialect.do_rollback(self.connection)
  File "/home/pot/.conda/envs/tf_2.4.1_cpu/lib/python3.8/site-packages/sqlalchemy/engine/default.py", line 666, in do_rollback
    dbapi_connection.rollback()
sqlalchemy.exc.ProgrammingError: (sqlite3.ProgrammingError) SQLite objects created in a thread can only be used in that same thread. The object was created in thread id 139992366233344 and this is thread id 139992426592064.
(Background on this error at: http://sqlalche.me/e/14/f405)
2021-04-22 18:27:52,636 - ERROR - Exception during reset or similar
Traceback (most recent call last):
  File "/home/pot/.conda/envs/tf_2.4.1_cpu/lib/python3.8/site-packages/sqlalchemy/pool/base.py", line 670, in _finalize_fairy
    fairy._reset(pool)
  File "/home/pot/.conda/envs/tf_2.4.1_cpu/lib/python3.8/site-packages/sqlalchemy/pool/base.py", line 875, in _reset
    pool._dialect.do_rollback(self)
  File "/home/pot/.conda/envs/tf_2.4.1_cpu/lib/python3.8/site-packages/sqlalchemy/engine/default.py", line 666, in do_rollback
    dbapi_connection.rollback()
sqlite3.ProgrammingError: SQLite objects created in a thread can only be used in that same thread. The object was created in thread id 139992366233344 and this is thread id 139992426592064.
2021-04-22 18:27:52,637 - ERROR - Exception closing connection <sqlite3.Connection object at 0x7f5283717c60>
Traceback (most recent call last):
  File "/home/pot/.conda/envs/tf_2.4.1_cpu/lib/python3.8/site-packages/sqlalchemy/pool/base.py", line 670, in _finalize_fairy
    fairy._reset(pool)
  File "/home/pot/.conda/envs/tf_2.4.1_cpu/lib/python3.8/site-packages/sqlalchemy/pool/base.py", line 875, in _reset
    pool._dialect.do_rollback(self)
  File "/home/pot/.conda/envs/tf_2.4.1_cpu/lib/python3.8/site-packages/sqlalchemy/engine/default.py", line 666, in do_rollback
    dbapi_connection.rollback()
sqlite3.ProgrammingError: SQLite objects created in a thread can only be used in that same thread. The object was created in thread id 139992366233344 and this is thread id 139992426592064.

During handling of the above exception, another exception occurred:

Traceback (most recent call last):
  File "/home/pot/.conda/envs/tf_2.4.1_cpu/lib/python3.8/site-packages/sqlalchemy/pool/base.py", line 238, in _close_connection
    self._dialect.do_close(connection)
  File "/home/pot/.conda/envs/tf_2.4.1_cpu/lib/python3.8/site-packages/sqlalchemy/engine/default.py", line 672, in do_close
    dbapi_connection.close()
sqlite3.ProgrammingError: SQLite objects created in a thread can only be used in that same thread. The object was created in thread id 139992366233344 and this is thread id 139992426592064.
2021-04-22 18:27:52,640 - INFO - BEGIN (implicit)
2021-04-22 18:27:52,640 - INFO - SELECT document.id AS document_id, document.name AS document_name, document.url AS document_url, document.export_date AS document_export_date, document.create_date AS document_create_date, document.update_date AS document_update_date, document.type_id AS document_type_id, document.status_id AS document_status_id, document_type_1.id AS document_type_1_id, document_type_1.name AS document_type_1_name, document_type_1.description AS document_type_1_description, document_type_1.create_date AS document_type_1_create_date, document_type_1.update_date AS document_type_1_update_date, status_1.id AS status_1_id, status_1.status_code AS status_1_status_code, status_1.status_name AS status_1_status_name, status_1.description AS status_1_description, status_1.create_date AS status_1_create_date, status_1.update_date AS status_1_update_date, document_split_1.id AS document_split_1_id, document_split_1.name AS document_split_1_name, document_split_1.value AS document_split_1_value, document_split_1.is_extracted AS document_split_1_is_extracted, document_split_1.url AS document_split_1_url, document_split_1.create_date AS document_split_1_create_date, document_split_1.update_date AS document_split_1_update_date, document_split_1.type_id AS document_split_1_type_id, document_split_1.document_id AS document_split_1_document_id 
FROM document LEFT OUTER JOIN document_type AS document_type_1 ON document_type_1.id = document.type_id LEFT OUTER JOIN status AS status_1 ON status_1.id = document.status_id LEFT OUTER JOIN document_split AS document_split_1 ON document.id = document_split_1.document_id 
WHERE document.type_id = ? AND document.status_id = ? AND document.export_date = ? ORDER BY document.export_date DESC
2021-04-22 18:27:52,641 - INFO - [cached since 664.7s ago] ('1', 3, '2021-04-22')
2021-04-22 18:27:52,642 - INFO - ROLLBACK
2021-04-22 18:27:52,643 - ERROR - Exception in ASGI application
Traceback (most recent call last):
  File "/home/pot/.conda/envs/tf_2.4.1_cpu/lib/python3.8/site-packages/uvicorn/protocols/http/h11_impl.py", line 396, in run_asgi
    result = await app(self.scope, self.receive, self.send)
  File "/home/pot/.conda/envs/tf_2.4.1_cpu/lib/python3.8/site-packages/uvicorn/middleware/proxy_headers.py", line 45, in __call__
    return await self.app(scope, receive, send)
  File "/home/pot/.conda/envs/tf_2.4.1_cpu/lib/python3.8/site-packages/uvicorn/middleware/debug.py", line 81, in __call__
    raise exc from None
  File "/home/pot/.conda/envs/tf_2.4.1_cpu/lib/python3.8/site-packages/uvicorn/middleware/debug.py", line 78, in __call__
    await self.app(scope, receive, inner_send)
  File "/home/pot/.conda/envs/tf_2.4.1_cpu/lib/python3.8/site-packages/fastapi/applications.py", line 199, in __call__
    await super().__call__(scope, receive, send)
  File "/home/pot/.conda/envs/tf_2.4.1_cpu/lib/python3.8/site-packages/starlette/applications.py", line 111, in __call__
    await self.middleware_stack(scope, receive, send)
  File "/home/pot/.conda/envs/tf_2.4.1_cpu/lib/python3.8/site-packages/starlette/middleware/errors.py", line 181, in __call__
    raise exc from None
  File "/home/pot/.conda/envs/tf_2.4.1_cpu/lib/python3.8/site-packages/starlette/middleware/errors.py", line 159, in __call__
    await self.app(scope, receive, _send)
  File "/home/pot/.conda/envs/tf_2.4.1_cpu/lib/python3.8/site-packages/starlette/middleware/base.py", line 25, in __call__
    response = await self.dispatch_func(request, self.call_next)
  File "main.py", line 44, in db_session_middleware
    request.state.db.close()
  File "/home/pot/.conda/envs/tf_2.4.1_cpu/lib/python3.8/site-packages/sqlalchemy/orm/session.py", line 1723, in close
    self._close_impl(invalidate=False)
  File "/home/pot/.conda/envs/tf_2.4.1_cpu/lib/python3.8/site-packages/sqlalchemy/orm/session.py", line 1765, in _close_impl
    transaction.close(invalidate)
  File "/home/pot/.conda/envs/tf_2.4.1_cpu/lib/python3.8/site-packages/sqlalchemy/orm/session.py", line 923, in close
    transaction.close()
  File "/home/pot/.conda/envs/tf_2.4.1_cpu/lib/python3.8/site-packages/sqlalchemy/engine/base.py", line 2221, in close
    self._do_close()
  File "/home/pot/.conda/envs/tf_2.4.1_cpu/lib/python3.8/site-packages/sqlalchemy/engine/base.py", line 2430, in _do_close
    self._close_impl()
  File "/home/pot/.conda/envs/tf_2.4.1_cpu/lib/python3.8/site-packages/sqlalchemy/engine/base.py", line 2416, in _close_impl
    self._connection_rollback_impl()
  File "/home/pot/.conda/envs/tf_2.4.1_cpu/lib/python3.8/site-packages/sqlalchemy/engine/base.py", line 2408, in _connection_rollback_impl
    self.connection._rollback_impl()
  File "/home/pot/.conda/envs/tf_2.4.1_cpu/lib/python3.8/site-packages/sqlalchemy/engine/base.py", line 898, in _rollback_impl
    self._handle_dbapi_exception(e, None, None, None, None)
  File "/home/pot/.conda/envs/tf_2.4.1_cpu/lib/python3.8/site-packages/sqlalchemy/engine/base.py", line 1929, in _handle_dbapi_exception
    util.raise_(
  File "/home/pot/.conda/envs/tf_2.4.1_cpu/lib/python3.8/site-packages/sqlalchemy/util/compat.py", line 211, in raise_
    raise exception
  File "/home/pot/.conda/envs/tf_2.4.1_cpu/lib/python3.8/site-packages/sqlalchemy/engine/base.py", line 896, in _rollback_impl
    self.engine.dialect.do_rollback(self.connection)
  File "/home/pot/.conda/envs/tf_2.4.1_cpu/lib/python3.8/site-packages/sqlalchemy/engine/default.py", line 666, in do_rollback
    dbapi_connection.rollback()
sqlalchemy.exc.ProgrammingError: (sqlite3.ProgrammingError) SQLite objects created in a thread can only be used in that same thread. The object was created in thread id 139992366233344 and this is thread id 139992426592064.
(Background on this error at: http://sqlalche.me/e/14/f405)
