2021-05-09 10:43:37,134 - WARNING - Invalid HTTP request received.
Traceback (most recent call last):
  File "/opt/jupyter/lib/python3.8/site-packages/uvicorn/protocols/http/h11_impl.py", line 172, in handle_events
    event = self.conn.next_event()
  File "/opt/jupyter/lib/python3.8/site-packages/h11/_connection.py", line 443, in next_event
    exc._reraise_as_remote_protocol_error()
  File "/opt/jupyter/lib/python3.8/site-packages/h11/_util.py", line 76, in _reraise_as_remote_protocol_error
    raise self
  File "/opt/jupyter/lib/python3.8/site-packages/h11/_connection.py", line 425, in next_event
    event = self._extract_next_receive_event()
  File "/opt/jupyter/lib/python3.8/site-packages/h11/_connection.py", line 367, in _extract_next_receive_event
    event = self._reader(self._receive_buffer)
  File "/opt/jupyter/lib/python3.8/site-packages/h11/_readers.py", line 68, in maybe_read_from_IDLE_client
    raise LocalProtocolError("illegal request line")
h11._util.RemoteProtocolError: illegal request line
2021-05-09 20:42:54,456 - WARNING - Invalid HTTP request received.
Traceback (most recent call last):
  File "/opt/jupyter/lib/python3.8/site-packages/uvicorn/protocols/http/h11_impl.py", line 172, in handle_events
    event = self.conn.next_event()
  File "/opt/jupyter/lib/python3.8/site-packages/h11/_connection.py", line 443, in next_event
    exc._reraise_as_remote_protocol_error()
  File "/opt/jupyter/lib/python3.8/site-packages/h11/_util.py", line 76, in _reraise_as_remote_protocol_error
    raise self
  File "/opt/jupyter/lib/python3.8/site-packages/h11/_connection.py", line 425, in next_event
    event = self._extract_next_receive_event()
  File "/opt/jupyter/lib/python3.8/site-packages/h11/_connection.py", line 367, in _extract_next_receive_event
    event = self._reader(self._receive_buffer)
  File "/opt/jupyter/lib/python3.8/site-packages/h11/_readers.py", line 72, in maybe_read_from_IDLE_client
    matches = validate(
  File "/opt/jupyter/lib/python3.8/site-packages/h11/_util.py", line 88, in validate
    raise LocalProtocolError(msg)
h11._util.RemoteProtocolError: illegal request line: bytearray(b'OPTIONS sip:nm SIP/2.0')
2021-05-09 20:43:00,522 - WARNING - Invalid HTTP request received.
Traceback (most recent call last):
  File "/opt/jupyter/lib/python3.8/site-packages/uvicorn/protocols/http/h11_impl.py", line 172, in handle_events
    event = self.conn.next_event()
  File "/opt/jupyter/lib/python3.8/site-packages/h11/_connection.py", line 443, in next_event
    exc._reraise_as_remote_protocol_error()
  File "/opt/jupyter/lib/python3.8/site-packages/h11/_util.py", line 76, in _reraise_as_remote_protocol_error
    raise self
  File "/opt/jupyter/lib/python3.8/site-packages/h11/_connection.py", line 425, in next_event
    event = self._extract_next_receive_event()
  File "/opt/jupyter/lib/python3.8/site-packages/h11/_connection.py", line 367, in _extract_next_receive_event
    event = self._reader(self._receive_buffer)
  File "/opt/jupyter/lib/python3.8/site-packages/h11/_readers.py", line 71, in maybe_read_from_IDLE_client
    raise LocalProtocolError("no request line received")
h11._util.RemoteProtocolError: no request line received
2021-05-09 20:43:04,433 - WARNING - Invalid HTTP request received.
Traceback (most recent call last):
  File "/opt/jupyter/lib/python3.8/site-packages/uvicorn/protocols/http/h11_impl.py", line 172, in handle_events
    event = self.conn.next_event()
  File "/opt/jupyter/lib/python3.8/site-packages/h11/_connection.py", line 443, in next_event
    exc._reraise_as_remote_protocol_error()
  File "/opt/jupyter/lib/python3.8/site-packages/h11/_util.py", line 76, in _reraise_as_remote_protocol_error
    raise self
  File "/opt/jupyter/lib/python3.8/site-packages/h11/_connection.py", line 425, in next_event
    event = self._extract_next_receive_event()
  File "/opt/jupyter/lib/python3.8/site-packages/h11/_connection.py", line 367, in _extract_next_receive_event
    event = self._reader(self._receive_buffer)
  File "/opt/jupyter/lib/python3.8/site-packages/h11/_readers.py", line 72, in maybe_read_from_IDLE_client
    matches = validate(
  File "/opt/jupyter/lib/python3.8/site-packages/h11/_util.py", line 88, in validate
    raise LocalProtocolError(msg)
h11._util.RemoteProtocolError: illegal request line: bytearray(b'OPTIONS / RTSP/1.0')
2021-05-09 20:43:12,021 - WARNING - Invalid HTTP request received.
Traceback (most recent call last):
  File "/opt/jupyter/lib/python3.8/site-packages/uvicorn/protocols/http/h11_impl.py", line 172, in handle_events
    event = self.conn.next_event()
  File "/opt/jupyter/lib/python3.8/site-packages/h11/_connection.py", line 443, in next_event
    exc._reraise_as_remote_protocol_error()
  File "/opt/jupyter/lib/python3.8/site-packages/h11/_util.py", line 76, in _reraise_as_remote_protocol_error
    raise self
  File "/opt/jupyter/lib/python3.8/site-packages/h11/_connection.py", line 425, in next_event
    event = self._extract_next_receive_event()
  File "/opt/jupyter/lib/python3.8/site-packages/h11/_connection.py", line 367, in _extract_next_receive_event
    event = self._reader(self._receive_buffer)
  File "/opt/jupyter/lib/python3.8/site-packages/h11/_readers.py", line 68, in maybe_read_from_IDLE_client
    raise LocalProtocolError("illegal request line")
h11._util.RemoteProtocolError: illegal request line
2021-05-09 20:43:14,262 - WARNING - Invalid HTTP request received.
Traceback (most recent call last):
  File "/opt/jupyter/lib/python3.8/site-packages/uvicorn/protocols/http/h11_impl.py", line 172, in handle_events
    event = self.conn.next_event()
  File "/opt/jupyter/lib/python3.8/site-packages/h11/_connection.py", line 443, in next_event
    exc._reraise_as_remote_protocol_error()
  File "/opt/jupyter/lib/python3.8/site-packages/h11/_util.py", line 76, in _reraise_as_remote_protocol_error
    raise self
  File "/opt/jupyter/lib/python3.8/site-packages/h11/_connection.py", line 425, in next_event
    event = self._extract_next_receive_event()
  File "/opt/jupyter/lib/python3.8/site-packages/h11/_connection.py", line 367, in _extract_next_receive_event
    event = self._reader(self._receive_buffer)
  File "/opt/jupyter/lib/python3.8/site-packages/h11/_readers.py", line 68, in maybe_read_from_IDLE_client
    raise LocalProtocolError("illegal request line")
h11._util.RemoteProtocolError: illegal request line
2021-05-09 20:43:32,475 - WARNING - Invalid HTTP request received.
Traceback (most recent call last):
  File "/opt/jupyter/lib/python3.8/site-packages/uvicorn/protocols/http/h11_impl.py", line 172, in handle_events
    event = self.conn.next_event()
  File "/opt/jupyter/lib/python3.8/site-packages/h11/_connection.py", line 443, in next_event
    exc._reraise_as_remote_protocol_error()
  File "/opt/jupyter/lib/python3.8/site-packages/h11/_util.py", line 76, in _reraise_as_remote_protocol_error
    raise self
  File "/opt/jupyter/lib/python3.8/site-packages/h11/_connection.py", line 425, in next_event
    event = self._extract_next_receive_event()
  File "/opt/jupyter/lib/python3.8/site-packages/h11/_connection.py", line 367, in _extract_next_receive_event
    event = self._reader(self._receive_buffer)
  File "/opt/jupyter/lib/python3.8/site-packages/h11/_readers.py", line 68, in maybe_read_from_IDLE_client
    raise LocalProtocolError("illegal request line")
h11._util.RemoteProtocolError: illegal request line
2021-05-09 20:43:33,716 - WARNING - Invalid HTTP request received.
Traceback (most recent call last):
  File "/opt/jupyter/lib/python3.8/site-packages/uvicorn/protocols/http/h11_impl.py", line 172, in handle_events
    event = self.conn.next_event()
  File "/opt/jupyter/lib/python3.8/site-packages/h11/_connection.py", line 443, in next_event
    exc._reraise_as_remote_protocol_error()
  File "/opt/jupyter/lib/python3.8/site-packages/h11/_util.py", line 76, in _reraise_as_remote_protocol_error
    raise self
  File "/opt/jupyter/lib/python3.8/site-packages/h11/_connection.py", line 425, in next_event
    event = self._extract_next_receive_event()
  File "/opt/jupyter/lib/python3.8/site-packages/h11/_connection.py", line 367, in _extract_next_receive_event
    event = self._reader(self._receive_buffer)
  File "/opt/jupyter/lib/python3.8/site-packages/h11/_readers.py", line 68, in maybe_read_from_IDLE_client
    raise LocalProtocolError("illegal request line")
h11._util.RemoteProtocolError: illegal request line
2021-05-09 20:43:35,524 - WARNING - Invalid HTTP request received.
Traceback (most recent call last):
  File "/opt/jupyter/lib/python3.8/site-packages/uvicorn/protocols/http/h11_impl.py", line 172, in handle_events
    event = self.conn.next_event()
  File "/opt/jupyter/lib/python3.8/site-packages/h11/_connection.py", line 443, in next_event
    exc._reraise_as_remote_protocol_error()
  File "/opt/jupyter/lib/python3.8/site-packages/h11/_util.py", line 76, in _reraise_as_remote_protocol_error
    raise self
  File "/opt/jupyter/lib/python3.8/site-packages/h11/_connection.py", line 425, in next_event
    event = self._extract_next_receive_event()
  File "/opt/jupyter/lib/python3.8/site-packages/h11/_connection.py", line 367, in _extract_next_receive_event
    event = self._reader(self._receive_buffer)
  File "/opt/jupyter/lib/python3.8/site-packages/h11/_readers.py", line 68, in maybe_read_from_IDLE_client
    raise LocalProtocolError("illegal request line")
h11._util.RemoteProtocolError: illegal request line
2021-05-09 20:43:43,083 - WARNING - Invalid HTTP request received.
Traceback (most recent call last):
  File "/opt/jupyter/lib/python3.8/site-packages/uvicorn/protocols/http/h11_impl.py", line 172, in handle_events
    event = self.conn.next_event()
  File "/opt/jupyter/lib/python3.8/site-packages/h11/_connection.py", line 443, in next_event
    exc._reraise_as_remote_protocol_error()
  File "/opt/jupyter/lib/python3.8/site-packages/h11/_util.py", line 76, in _reraise_as_remote_protocol_error
    raise self
  File "/opt/jupyter/lib/python3.8/site-packages/h11/_connection.py", line 425, in next_event
    event = self._extract_next_receive_event()
  File "/opt/jupyter/lib/python3.8/site-packages/h11/_connection.py", line 367, in _extract_next_receive_event
    event = self._reader(self._receive_buffer)
  File "/opt/jupyter/lib/python3.8/site-packages/h11/_readers.py", line 68, in maybe_read_from_IDLE_client
    raise LocalProtocolError("illegal request line")
h11._util.RemoteProtocolError: illegal request line
2021-05-09 20:43:44,484 - WARNING - Invalid HTTP request received.
Traceback (most recent call last):
  File "/opt/jupyter/lib/python3.8/site-packages/uvicorn/protocols/http/h11_impl.py", line 172, in handle_events
    event = self.conn.next_event()
  File "/opt/jupyter/lib/python3.8/site-packages/h11/_connection.py", line 443, in next_event
    exc._reraise_as_remote_protocol_error()
  File "/opt/jupyter/lib/python3.8/site-packages/h11/_util.py", line 76, in _reraise_as_remote_protocol_error
    raise self
  File "/opt/jupyter/lib/python3.8/site-packages/h11/_connection.py", line 425, in next_event
    event = self._extract_next_receive_event()
  File "/opt/jupyter/lib/python3.8/site-packages/h11/_connection.py", line 367, in _extract_next_receive_event
    event = self._reader(self._receive_buffer)
  File "/opt/jupyter/lib/python3.8/site-packages/h11/_readers.py", line 68, in maybe_read_from_IDLE_client
    raise LocalProtocolError("illegal request line")
h11._util.RemoteProtocolError: illegal request line
2021-05-09 20:43:52,128 - WARNING - Invalid HTTP request received.
Traceback (most recent call last):
  File "/opt/jupyter/lib/python3.8/site-packages/uvicorn/protocols/http/h11_impl.py", line 172, in handle_events
    event = self.conn.next_event()
  File "/opt/jupyter/lib/python3.8/site-packages/h11/_connection.py", line 443, in next_event
    exc._reraise_as_remote_protocol_error()
  File "/opt/jupyter/lib/python3.8/site-packages/h11/_util.py", line 76, in _reraise_as_remote_protocol_error
    raise self
  File "/opt/jupyter/lib/python3.8/site-packages/h11/_connection.py", line 425, in next_event
    event = self._extract_next_receive_event()
  File "/opt/jupyter/lib/python3.8/site-packages/h11/_connection.py", line 367, in _extract_next_receive_event
    event = self._reader(self._receive_buffer)
  File "/opt/jupyter/lib/python3.8/site-packages/h11/_readers.py", line 68, in maybe_read_from_IDLE_client
    raise LocalProtocolError("illegal request line")
h11._util.RemoteProtocolError: illegal request line
2021-05-09 20:44:11,965 - WARNING - Invalid HTTP request received.
Traceback (most recent call last):
  File "/opt/jupyter/lib/python3.8/site-packages/uvicorn/protocols/http/h11_impl.py", line 172, in handle_events
    event = self.conn.next_event()
  File "/opt/jupyter/lib/python3.8/site-packages/h11/_connection.py", line 443, in next_event
    exc._reraise_as_remote_protocol_error()
  File "/opt/jupyter/lib/python3.8/site-packages/h11/_util.py", line 76, in _reraise_as_remote_protocol_error
    raise self
  File "/opt/jupyter/lib/python3.8/site-packages/h11/_connection.py", line 425, in next_event
    event = self._extract_next_receive_event()
  File "/opt/jupyter/lib/python3.8/site-packages/h11/_connection.py", line 367, in _extract_next_receive_event
    event = self._reader(self._receive_buffer)
  File "/opt/jupyter/lib/python3.8/site-packages/h11/_readers.py", line 68, in maybe_read_from_IDLE_client
    raise LocalProtocolError("illegal request line")
h11._util.RemoteProtocolError: illegal request line
2021-05-09 20:44:33,497 - WARNING - Invalid HTTP request received.
Traceback (most recent call last):
  File "/opt/jupyter/lib/python3.8/site-packages/uvicorn/protocols/http/h11_impl.py", line 172, in handle_events
    event = self.conn.next_event()
  File "/opt/jupyter/lib/python3.8/site-packages/h11/_connection.py", line 443, in next_event
    exc._reraise_as_remote_protocol_error()
  File "/opt/jupyter/lib/python3.8/site-packages/h11/_util.py", line 76, in _reraise_as_remote_protocol_error
    raise self
  File "/opt/jupyter/lib/python3.8/site-packages/h11/_connection.py", line 425, in next_event
    event = self._extract_next_receive_event()
  File "/opt/jupyter/lib/python3.8/site-packages/h11/_connection.py", line 367, in _extract_next_receive_event
    event = self._reader(self._receive_buffer)
  File "/opt/jupyter/lib/python3.8/site-packages/h11/_readers.py", line 68, in maybe_read_from_IDLE_client
    raise LocalProtocolError("illegal request line")
h11._util.RemoteProtocolError: illegal request line
2021-05-09 20:44:38,977 - WARNING - Invalid HTTP request received.
Traceback (most recent call last):
  File "/opt/jupyter/lib/python3.8/site-packages/uvicorn/protocols/http/h11_impl.py", line 172, in handle_events
    event = self.conn.next_event()
  File "/opt/jupyter/lib/python3.8/site-packages/h11/_connection.py", line 443, in next_event
    exc._reraise_as_remote_protocol_error()
  File "/opt/jupyter/lib/python3.8/site-packages/h11/_util.py", line 76, in _reraise_as_remote_protocol_error
    raise self
  File "/opt/jupyter/lib/python3.8/site-packages/h11/_connection.py", line 425, in next_event
    event = self._extract_next_receive_event()
  File "/opt/jupyter/lib/python3.8/site-packages/h11/_connection.py", line 367, in _extract_next_receive_event
    event = self._reader(self._receive_buffer)
  File "/opt/jupyter/lib/python3.8/site-packages/h11/_readers.py", line 68, in maybe_read_from_IDLE_client
    raise LocalProtocolError("illegal request line")
h11._util.RemoteProtocolError: illegal request line
2021-05-09 20:44:39,360 - WARNING - Invalid HTTP request received.
Traceback (most recent call last):
  File "/opt/jupyter/lib/python3.8/site-packages/uvicorn/protocols/http/h11_impl.py", line 172, in handle_events
    event = self.conn.next_event()
  File "/opt/jupyter/lib/python3.8/site-packages/h11/_connection.py", line 443, in next_event
    exc._reraise_as_remote_protocol_error()
  File "/opt/jupyter/lib/python3.8/site-packages/h11/_util.py", line 76, in _reraise_as_remote_protocol_error
    raise self
  File "/opt/jupyter/lib/python3.8/site-packages/h11/_connection.py", line 425, in next_event
    event = self._extract_next_receive_event()
  File "/opt/jupyter/lib/python3.8/site-packages/h11/_connection.py", line 367, in _extract_next_receive_event
    event = self._reader(self._receive_buffer)
  File "/opt/jupyter/lib/python3.8/site-packages/h11/_readers.py", line 68, in maybe_read_from_IDLE_client
    raise LocalProtocolError("illegal request line")
h11._util.RemoteProtocolError: illegal request line
2021-05-09 20:44:55,934 - WARNING - Invalid HTTP request received.
Traceback (most recent call last):
  File "/opt/jupyter/lib/python3.8/site-packages/uvicorn/protocols/http/h11_impl.py", line 172, in handle_events
    event = self.conn.next_event()
  File "/opt/jupyter/lib/python3.8/site-packages/h11/_connection.py", line 443, in next_event
    exc._reraise_as_remote_protocol_error()
  File "/opt/jupyter/lib/python3.8/site-packages/h11/_util.py", line 76, in _reraise_as_remote_protocol_error
    raise self
  File "/opt/jupyter/lib/python3.8/site-packages/h11/_connection.py", line 425, in next_event
    event = self._extract_next_receive_event()
  File "/opt/jupyter/lib/python3.8/site-packages/h11/_connection.py", line 367, in _extract_next_receive_event
    event = self._reader(self._receive_buffer)
  File "/opt/jupyter/lib/python3.8/site-packages/h11/_readers.py", line 72, in maybe_read_from_IDLE_client
    matches = validate(
  File "/opt/jupyter/lib/python3.8/site-packages/h11/_util.py", line 88, in validate
    raise LocalProtocolError(msg)
h11._util.RemoteProtocolError: illegal request line: bytearray(b'\x05\x04\x00\x01\x02\x80\x05\x01\x00\x03')
2021-05-09 20:44:56,317 - WARNING - Invalid HTTP request received.
Traceback (most recent call last):
  File "/opt/jupyter/lib/python3.8/site-packages/uvicorn/protocols/http/h11_impl.py", line 172, in handle_events
    event = self.conn.next_event()
  File "/opt/jupyter/lib/python3.8/site-packages/h11/_connection.py", line 443, in next_event
    exc._reraise_as_remote_protocol_error()
  File "/opt/jupyter/lib/python3.8/site-packages/h11/_util.py", line 76, in _reraise_as_remote_protocol_error
    raise self
  File "/opt/jupyter/lib/python3.8/site-packages/h11/_connection.py", line 425, in next_event
    event = self._extract_next_receive_event()
  File "/opt/jupyter/lib/python3.8/site-packages/h11/_connection.py", line 367, in _extract_next_receive_event
    event = self._reader(self._receive_buffer)
  File "/opt/jupyter/lib/python3.8/site-packages/h11/_readers.py", line 68, in maybe_read_from_IDLE_client
    raise LocalProtocolError("illegal request line")
h11._util.RemoteProtocolError: illegal request line
2021-05-09 20:44:56,852 - WARNING - Invalid HTTP request received.
Traceback (most recent call last):
  File "/opt/jupyter/lib/python3.8/site-packages/uvicorn/protocols/http/h11_impl.py", line 172, in handle_events
    event = self.conn.next_event()
  File "/opt/jupyter/lib/python3.8/site-packages/h11/_connection.py", line 443, in next_event
    exc._reraise_as_remote_protocol_error()
  File "/opt/jupyter/lib/python3.8/site-packages/h11/_util.py", line 76, in _reraise_as_remote_protocol_error
    raise self
  File "/opt/jupyter/lib/python3.8/site-packages/h11/_connection.py", line 425, in next_event
    event = self._extract_next_receive_event()
  File "/opt/jupyter/lib/python3.8/site-packages/h11/_connection.py", line 367, in _extract_next_receive_event
    event = self._reader(self._receive_buffer)
  File "/opt/jupyter/lib/python3.8/site-packages/h11/_readers.py", line 68, in maybe_read_from_IDLE_client
    raise LocalProtocolError("illegal request line")
h11._util.RemoteProtocolError: illegal request line
2021-05-09 20:44:57,009 - WARNING - Invalid HTTP request received.
Traceback (most recent call last):
  File "/opt/jupyter/lib/python3.8/site-packages/uvicorn/protocols/http/h11_impl.py", line 172, in handle_events
    event = self.conn.next_event()
  File "/opt/jupyter/lib/python3.8/site-packages/h11/_connection.py", line 443, in next_event
    exc._reraise_as_remote_protocol_error()
  File "/opt/jupyter/lib/python3.8/site-packages/h11/_util.py", line 76, in _reraise_as_remote_protocol_error
    raise self
  File "/opt/jupyter/lib/python3.8/site-packages/h11/_connection.py", line 425, in next_event
    event = self._extract_next_receive_event()
  File "/opt/jupyter/lib/python3.8/site-packages/h11/_connection.py", line 367, in _extract_next_receive_event
    event = self._reader(self._receive_buffer)
  File "/opt/jupyter/lib/python3.8/site-packages/h11/_readers.py", line 68, in maybe_read_from_IDLE_client
    raise LocalProtocolError("illegal request line")
h11._util.RemoteProtocolError: illegal request line
2021-05-09 20:44:57,411 - WARNING - Invalid HTTP request received.
Traceback (most recent call last):
  File "/opt/jupyter/lib/python3.8/site-packages/uvicorn/protocols/http/h11_impl.py", line 172, in handle_events
    event = self.conn.next_event()
  File "/opt/jupyter/lib/python3.8/site-packages/h11/_connection.py", line 443, in next_event
    exc._reraise_as_remote_protocol_error()
  File "/opt/jupyter/lib/python3.8/site-packages/h11/_util.py", line 76, in _reraise_as_remote_protocol_error
    raise self
  File "/opt/jupyter/lib/python3.8/site-packages/h11/_connection.py", line 425, in next_event
    event = self._extract_next_receive_event()
  File "/opt/jupyter/lib/python3.8/site-packages/h11/_connection.py", line 367, in _extract_next_receive_event
    event = self._reader(self._receive_buffer)
  File "/opt/jupyter/lib/python3.8/site-packages/h11/_readers.py", line 72, in maybe_read_from_IDLE_client
    matches = validate(
  File "/opt/jupyter/lib/python3.8/site-packages/h11/_util.py", line 88, in validate
    raise LocalProtocolError(msg)
h11._util.RemoteProtocolError: illegal request line: bytearray(b'HELP')
2021-05-09 20:45:03,068 - WARNING - Invalid HTTP request received.
Traceback (most recent call last):
  File "/opt/jupyter/lib/python3.8/site-packages/uvicorn/protocols/http/h11_impl.py", line 172, in handle_events
    event = self.conn.next_event()
  File "/opt/jupyter/lib/python3.8/site-packages/h11/_connection.py", line 443, in next_event
    exc._reraise_as_remote_protocol_error()
  File "/opt/jupyter/lib/python3.8/site-packages/h11/_util.py", line 76, in _reraise_as_remote_protocol_error
    raise self
  File "/opt/jupyter/lib/python3.8/site-packages/h11/_connection.py", line 425, in next_event
    event = self._extract_next_receive_event()
  File "/opt/jupyter/lib/python3.8/site-packages/h11/_connection.py", line 367, in _extract_next_receive_event
    event = self._reader(self._receive_buffer)
  File "/opt/jupyter/lib/python3.8/site-packages/h11/_readers.py", line 68, in maybe_read_from_IDLE_client
    raise LocalProtocolError("illegal request line")
h11._util.RemoteProtocolError: illegal request line
2021-05-09 20:45:03,788 - WARNING - Invalid HTTP request received.
Traceback (most recent call last):
  File "/opt/jupyter/lib/python3.8/site-packages/uvicorn/protocols/http/h11_impl.py", line 172, in handle_events
    event = self.conn.next_event()
  File "/opt/jupyter/lib/python3.8/site-packages/h11/_connection.py", line 443, in next_event
    exc._reraise_as_remote_protocol_error()
  File "/opt/jupyter/lib/python3.8/site-packages/h11/_util.py", line 76, in _reraise_as_remote_protocol_error
    raise self
  File "/opt/jupyter/lib/python3.8/site-packages/h11/_connection.py", line 425, in next_event
    event = self._extract_next_receive_event()
  File "/opt/jupyter/lib/python3.8/site-packages/h11/_connection.py", line 367, in _extract_next_receive_event
    event = self._reader(self._receive_buffer)
  File "/opt/jupyter/lib/python3.8/site-packages/h11/_readers.py", line 68, in maybe_read_from_IDLE_client
    raise LocalProtocolError("illegal request line")
h11._util.RemoteProtocolError: illegal request line
2021-05-09 20:45:04,509 - WARNING - Invalid HTTP request received.
Traceback (most recent call last):
  File "/opt/jupyter/lib/python3.8/site-packages/uvicorn/protocols/http/h11_impl.py", line 172, in handle_events
    event = self.conn.next_event()
  File "/opt/jupyter/lib/python3.8/site-packages/h11/_connection.py", line 443, in next_event
    exc._reraise_as_remote_protocol_error()
  File "/opt/jupyter/lib/python3.8/site-packages/h11/_util.py", line 76, in _reraise_as_remote_protocol_error
    raise self
  File "/opt/jupyter/lib/python3.8/site-packages/h11/_connection.py", line 425, in next_event
    event = self._extract_next_receive_event()
  File "/opt/jupyter/lib/python3.8/site-packages/h11/_connection.py", line 367, in _extract_next_receive_event
    event = self._reader(self._receive_buffer)
  File "/opt/jupyter/lib/python3.8/site-packages/h11/_readers.py", line 68, in maybe_read_from_IDLE_client
    raise LocalProtocolError("illegal request line")
h11._util.RemoteProtocolError: illegal request line
2021-05-09 20:45:15,627 - WARNING - Invalid HTTP request received.
Traceback (most recent call last):
  File "/opt/jupyter/lib/python3.8/site-packages/uvicorn/protocols/http/h11_impl.py", line 172, in handle_events
    event = self.conn.next_event()
  File "/opt/jupyter/lib/python3.8/site-packages/h11/_connection.py", line 443, in next_event
    exc._reraise_as_remote_protocol_error()
  File "/opt/jupyter/lib/python3.8/site-packages/h11/_util.py", line 76, in _reraise_as_remote_protocol_error
    raise self
  File "/opt/jupyter/lib/python3.8/site-packages/h11/_connection.py", line 425, in next_event
    event = self._extract_next_receive_event()
  File "/opt/jupyter/lib/python3.8/site-packages/h11/_connection.py", line 367, in _extract_next_receive_event
    event = self._reader(self._receive_buffer)
  File "/opt/jupyter/lib/python3.8/site-packages/h11/_readers.py", line 68, in maybe_read_from_IDLE_client
    raise LocalProtocolError("illegal request line")
h11._util.RemoteProtocolError: illegal request line
2021-05-09 20:45:16,006 - WARNING - Invalid HTTP request received.
Traceback (most recent call last):
  File "/opt/jupyter/lib/python3.8/site-packages/uvicorn/protocols/http/h11_impl.py", line 172, in handle_events
    event = self.conn.next_event()
  File "/opt/jupyter/lib/python3.8/site-packages/h11/_connection.py", line 443, in next_event
    exc._reraise_as_remote_protocol_error()
  File "/opt/jupyter/lib/python3.8/site-packages/h11/_util.py", line 76, in _reraise_as_remote_protocol_error
    raise self
  File "/opt/jupyter/lib/python3.8/site-packages/h11/_connection.py", line 425, in next_event
    event = self._extract_next_receive_event()
  File "/opt/jupyter/lib/python3.8/site-packages/h11/_connection.py", line 367, in _extract_next_receive_event
    event = self._reader(self._receive_buffer)
  File "/opt/jupyter/lib/python3.8/site-packages/h11/_readers.py", line 68, in maybe_read_from_IDLE_client
    raise LocalProtocolError("illegal request line")
h11._util.RemoteProtocolError: illegal request line
2021-05-09 20:45:31,804 - WARNING - Invalid HTTP request received.
Traceback (most recent call last):
  File "/opt/jupyter/lib/python3.8/site-packages/uvicorn/protocols/http/h11_impl.py", line 172, in handle_events
    event = self.conn.next_event()
  File "/opt/jupyter/lib/python3.8/site-packages/h11/_connection.py", line 443, in next_event
    exc._reraise_as_remote_protocol_error()
  File "/opt/jupyter/lib/python3.8/site-packages/h11/_util.py", line 76, in _reraise_as_remote_protocol_error
    raise self
  File "/opt/jupyter/lib/python3.8/site-packages/h11/_connection.py", line 425, in next_event
    event = self._extract_next_receive_event()
  File "/opt/jupyter/lib/python3.8/site-packages/h11/_connection.py", line 367, in _extract_next_receive_event
    event = self._reader(self._receive_buffer)
  File "/opt/jupyter/lib/python3.8/site-packages/h11/_readers.py", line 68, in maybe_read_from_IDLE_client
    raise LocalProtocolError("illegal request line")
h11._util.RemoteProtocolError: illegal request line
2021-05-09 20:45:32,445 - WARNING - Invalid HTTP request received.
Traceback (most recent call last):
  File "/opt/jupyter/lib/python3.8/site-packages/uvicorn/protocols/http/h11_impl.py", line 172, in handle_events
    event = self.conn.next_event()
  File "/opt/jupyter/lib/python3.8/site-packages/h11/_connection.py", line 443, in next_event
    exc._reraise_as_remote_protocol_error()
  File "/opt/jupyter/lib/python3.8/site-packages/h11/_util.py", line 76, in _reraise_as_remote_protocol_error
    raise self
  File "/opt/jupyter/lib/python3.8/site-packages/h11/_connection.py", line 425, in next_event
    event = self._extract_next_receive_event()
  File "/opt/jupyter/lib/python3.8/site-packages/h11/_connection.py", line 367, in _extract_next_receive_event
    event = self._reader(self._receive_buffer)
  File "/opt/jupyter/lib/python3.8/site-packages/h11/_readers.py", line 68, in maybe_read_from_IDLE_client
    raise LocalProtocolError("illegal request line")
h11._util.RemoteProtocolError: illegal request line
2021-05-09 20:45:37,916 - WARNING - Invalid HTTP request received.
Traceback (most recent call last):
  File "/opt/jupyter/lib/python3.8/site-packages/uvicorn/protocols/http/h11_impl.py", line 172, in handle_events
    event = self.conn.next_event()
  File "/opt/jupyter/lib/python3.8/site-packages/h11/_connection.py", line 443, in next_event
    exc._reraise_as_remote_protocol_error()
  File "/opt/jupyter/lib/python3.8/site-packages/h11/_util.py", line 76, in _reraise_as_remote_protocol_error
    raise self
  File "/opt/jupyter/lib/python3.8/site-packages/h11/_connection.py", line 425, in next_event
    event = self._extract_next_receive_event()
  File "/opt/jupyter/lib/python3.8/site-packages/h11/_connection.py", line 367, in _extract_next_receive_event
    event = self._reader(self._receive_buffer)
  File "/opt/jupyter/lib/python3.8/site-packages/h11/_readers.py", line 75, in maybe_read_from_IDLE_client
    return Request(
  File "/opt/jupyter/lib/python3.8/site-packages/h11/_events.py", line 71, in __init__
    self._validate()
  File "/opt/jupyter/lib/python3.8/site-packages/h11/_events.py", line 140, in _validate
    raise LocalProtocolError("Missing mandatory Host: header")
h11._util.RemoteProtocolError: Missing mandatory Host: header
2021-05-09 20:45:48,472 - WARNING - Invalid HTTP request received.
Traceback (most recent call last):
  File "/opt/jupyter/lib/python3.8/site-packages/uvicorn/protocols/http/h11_impl.py", line 172, in handle_events
    event = self.conn.next_event()
  File "/opt/jupyter/lib/python3.8/site-packages/h11/_connection.py", line 443, in next_event
    exc._reraise_as_remote_protocol_error()
  File "/opt/jupyter/lib/python3.8/site-packages/h11/_util.py", line 76, in _reraise_as_remote_protocol_error
    raise self
  File "/opt/jupyter/lib/python3.8/site-packages/h11/_connection.py", line 425, in next_event
    event = self._extract_next_receive_event()
  File "/opt/jupyter/lib/python3.8/site-packages/h11/_connection.py", line 367, in _extract_next_receive_event
    event = self._reader(self._receive_buffer)
  File "/opt/jupyter/lib/python3.8/site-packages/h11/_readers.py", line 68, in maybe_read_from_IDLE_client
    raise LocalProtocolError("illegal request line")
h11._util.RemoteProtocolError: illegal request line
2021-05-09 20:45:59,029 - WARNING - Invalid HTTP request received.
Traceback (most recent call last):
  File "/opt/jupyter/lib/python3.8/site-packages/uvicorn/protocols/http/h11_impl.py", line 172, in handle_events
    event = self.conn.next_event()
  File "/opt/jupyter/lib/python3.8/site-packages/h11/_connection.py", line 443, in next_event
    exc._reraise_as_remote_protocol_error()
  File "/opt/jupyter/lib/python3.8/site-packages/h11/_util.py", line 76, in _reraise_as_remote_protocol_error
    raise self
  File "/opt/jupyter/lib/python3.8/site-packages/h11/_connection.py", line 425, in next_event
    event = self._extract_next_receive_event()
  File "/opt/jupyter/lib/python3.8/site-packages/h11/_connection.py", line 367, in _extract_next_receive_event
    event = self._reader(self._receive_buffer)
  File "/opt/jupyter/lib/python3.8/site-packages/h11/_readers.py", line 68, in maybe_read_from_IDLE_client
    raise LocalProtocolError("illegal request line")
h11._util.RemoteProtocolError: illegal request line
2021-05-09 20:46:14,675 - WARNING - Invalid HTTP request received.
Traceback (most recent call last):
  File "/opt/jupyter/lib/python3.8/site-packages/uvicorn/protocols/http/h11_impl.py", line 172, in handle_events
    event = self.conn.next_event()
  File "/opt/jupyter/lib/python3.8/site-packages/h11/_connection.py", line 443, in next_event
    exc._reraise_as_remote_protocol_error()
  File "/opt/jupyter/lib/python3.8/site-packages/h11/_util.py", line 76, in _reraise_as_remote_protocol_error
    raise self
  File "/opt/jupyter/lib/python3.8/site-packages/h11/_connection.py", line 425, in next_event
    event = self._extract_next_receive_event()
  File "/opt/jupyter/lib/python3.8/site-packages/h11/_connection.py", line 367, in _extract_next_receive_event
    event = self._reader(self._receive_buffer)
  File "/opt/jupyter/lib/python3.8/site-packages/h11/_readers.py", line 75, in maybe_read_from_IDLE_client
    return Request(
  File "/opt/jupyter/lib/python3.8/site-packages/h11/_events.py", line 71, in __init__
    self._validate()
  File "/opt/jupyter/lib/python3.8/site-packages/h11/_events.py", line 140, in _validate
    raise LocalProtocolError("Missing mandatory Host: header")
h11._util.RemoteProtocolError: Missing mandatory Host: header
2021-05-09 20:46:15,197 - WARNING - Invalid HTTP request received.
Traceback (most recent call last):
  File "/opt/jupyter/lib/python3.8/site-packages/uvicorn/protocols/http/h11_impl.py", line 172, in handle_events
    event = self.conn.next_event()
  File "/opt/jupyter/lib/python3.8/site-packages/h11/_connection.py", line 443, in next_event
    exc._reraise_as_remote_protocol_error()
  File "/opt/jupyter/lib/python3.8/site-packages/h11/_util.py", line 76, in _reraise_as_remote_protocol_error
    raise self
  File "/opt/jupyter/lib/python3.8/site-packages/h11/_connection.py", line 425, in next_event
    event = self._extract_next_receive_event()
  File "/opt/jupyter/lib/python3.8/site-packages/h11/_connection.py", line 367, in _extract_next_receive_event
    event = self._reader(self._receive_buffer)
  File "/opt/jupyter/lib/python3.8/site-packages/h11/_readers.py", line 68, in maybe_read_from_IDLE_client
    raise LocalProtocolError("illegal request line")
h11._util.RemoteProtocolError: illegal request line
2021-05-09 20:46:35,933 - WARNING - Invalid HTTP request received.
Traceback (most recent call last):
  File "/opt/jupyter/lib/python3.8/site-packages/uvicorn/protocols/http/h11_impl.py", line 172, in handle_events
    event = self.conn.next_event()
  File "/opt/jupyter/lib/python3.8/site-packages/h11/_connection.py", line 443, in next_event
    exc._reraise_as_remote_protocol_error()
  File "/opt/jupyter/lib/python3.8/site-packages/h11/_util.py", line 76, in _reraise_as_remote_protocol_error
    raise self
  File "/opt/jupyter/lib/python3.8/site-packages/h11/_connection.py", line 425, in next_event
    event = self._extract_next_receive_event()
  File "/opt/jupyter/lib/python3.8/site-packages/h11/_connection.py", line 367, in _extract_next_receive_event
    event = self._reader(self._receive_buffer)
  File "/opt/jupyter/lib/python3.8/site-packages/h11/_readers.py", line 68, in maybe_read_from_IDLE_client
    raise LocalProtocolError("illegal request line")
h11._util.RemoteProtocolError: illegal request line
2021-05-09 20:46:36,314 - WARNING - Invalid HTTP request received.
Traceback (most recent call last):
  File "/opt/jupyter/lib/python3.8/site-packages/uvicorn/protocols/http/h11_impl.py", line 172, in handle_events
    event = self.conn.next_event()
  File "/opt/jupyter/lib/python3.8/site-packages/h11/_connection.py", line 443, in next_event
    exc._reraise_as_remote_protocol_error()
  File "/opt/jupyter/lib/python3.8/site-packages/h11/_util.py", line 76, in _reraise_as_remote_protocol_error
    raise self
  File "/opt/jupyter/lib/python3.8/site-packages/h11/_connection.py", line 425, in next_event
    event = self._extract_next_receive_event()
  File "/opt/jupyter/lib/python3.8/site-packages/h11/_connection.py", line 367, in _extract_next_receive_event
    event = self._reader(self._receive_buffer)
  File "/opt/jupyter/lib/python3.8/site-packages/h11/_readers.py", line 68, in maybe_read_from_IDLE_client
    raise LocalProtocolError("illegal request line")
h11._util.RemoteProtocolError: illegal request line
2021-05-09 20:49:29,911 - WARNING - Invalid HTTP request received.
Traceback (most recent call last):
  File "/opt/jupyter/lib/python3.8/site-packages/uvicorn/protocols/http/h11_impl.py", line 172, in handle_events
    event = self.conn.next_event()
  File "/opt/jupyter/lib/python3.8/site-packages/h11/_connection.py", line 443, in next_event
    exc._reraise_as_remote_protocol_error()
  File "/opt/jupyter/lib/python3.8/site-packages/h11/_util.py", line 76, in _reraise_as_remote_protocol_error
    raise self
  File "/opt/jupyter/lib/python3.8/site-packages/h11/_connection.py", line 425, in next_event
    event = self._extract_next_receive_event()
  File "/opt/jupyter/lib/python3.8/site-packages/h11/_connection.py", line 367, in _extract_next_receive_event
    event = self._reader(self._receive_buffer)
  File "/opt/jupyter/lib/python3.8/site-packages/h11/_readers.py", line 68, in maybe_read_from_IDLE_client
    raise LocalProtocolError("illegal request line")
h11._util.RemoteProtocolError: illegal request line
